Workbook
Name Cash: FCFF!$G$32
Name tax: [1]DCF!$D$26
Name WACC: [2]WACC!$O$19

Sheet FCFF
J2: Scenario | K2: Base
B3: Sysco Valuation Model
B4: Year Ended June 2025) | D4: Actuals | G4: Forecasts
B5: Year | C5: ='Income Statement'!F8 -> JUN '22 | D5: ='Income Statement'!E8 -> JUN '23 | E5: ='Income Statement'!D8 -> JUN '24 | F5: ='Income Statement'!C8 -> JUN '25 | G5: JUN'26 | H5: JUN'27 | I5: JUNE'28 | J5: JUN'29 | K5: JUN'30
B6: Sales | C6: ='All financial statements 21-25'!C10 -> 68636.146 | D6: ='All financial statements 21-25'!D10 -> 76324.675 | E6: ='All financial statements 21-25'!E10 -> 78844 | F6: ='All financial statements 21-25'!F10 -> 81370 | G6: =G61 -> 84624.8 | H6: =H61 -> 96432.916 | I6: =I61 -> 108412.4 | J6: =J61 -> 113290.96 | K6: =K61 -> 118389.05
B7: COGS | C7: =-'All financial statements 21-25'!C11 -> -56421.622 | D7: =-'All financial statements 21-25'!D11 -> -62474.678 | E7: =-'All financial statements 21-25'!E11 -> -65092 | F7: =-'All financial statements 21-25'!F11 -> -67332 | G7: =G66 -> -69680.842 | H7: =H66 -> -79303.753 | I7: =I66 -> -89017.769 | J7: =J66 -> -93034.818 | K7: =K66 -> -97232.635
B8: Gross Profit | C8: =C7+C6 -> 12214.524 | D8: =D7+D6 -> 13849.997 | E8: =E7+E6 -> 13752 | F8: =F7+F6 -> 14038 | G8: =G7+G6 -> 14943.958 | H8: =H7+H6 -> 17129.163 | I8: =I7+I6 -> 19394.628 | J8: =J7+J6 -> 20256.137 | K8: =K7+K6 -> 21156.413
B9: R&D | G9: =F57 -> 0.032037948 | H9: =G57 -> 0.04 | I9: =H57 -> 0.045 | J9: =I57 -> 0.045 | K9: =J57 -> 0.045
B10: SG&A | C10: =-'All financial statements 21-25'!C17 -> -9784.725 | D10: =-'All financial statements 21-25'!D17 -> -10708.566 | E10: =-'All financial statements 21-25'!E17 -> -10270 | F10: =-'All financial statements 21-25'!F17 -> -10526 | G10: =G69 -> -11001.224 | H10: =H69 -> -12536.279 | I10: =I69 -> -14093.612 | J10: =J69 -> -14727.824 | K10: =K69 -> -15390.576
B11: EBITDA | C11: =C8+C9+C10 -> 2429.799 | D11: =D8+D9+D10 -> 3141.431 | E11: =E8+E9+E10 -> 3482 | F11: =F8+F9+F10 -> 3512 | G11: =G8+G9+G10 -> 3942.7664 | H11: =H8+H9+H10 -> 4592.9235 | I11: =I8+I9+I10 -> 5301.0617 | J11: =J8+J9+J10 -> 5528.3575 | K11: =K8+K9+K10 -> 5765.8815
B12: Depreciation | C12: =-'All financial statements 21-25'!C130 -> -880.933 | D12: =-'All financial statements 21-25'!D130 -> -888.677 | E12: =-'All financial statements 21-25'!E130 -> -997 | F12: =-'All financial statements 21-25'!F130 -> -1086 | G12: =-G94 -> -1060.9548 | H12: =-H94 -> -1208.995 | I12: =-I94 -> -1359.1837 | J12: =-J94 -> -1420.347 | K12: =-K94 -> -1484.2626
B13: EBIT | C13: =C11+C12 -> 1548.866 | D13: =D11+D12 -> 2252.754 | E13: =E11+E12 -> 2485 | F13: =F11+F12 -> 2426 | G13: =G11+G12 -> 2881.8116 | H13: =H11+H12 -> 3383.9285 | I13: =I11+I12 -> 3941.878 | J13: =J11+J12 -> 4108.0105 | K13: =K11+K12 -> 4281.619
B14: EBIT % Sales | C14: =C13/C6 -> 0.022566331 | D14: =D13/D6 -> 0.029515409 | E14: =E13/E6 -> 0.031517934 | F14: =F13/F6 -> 0.029814428 | G14: =G13/G6 -> 0.034053984 | H14: =H13/H6 -> 0.035091011 | I14: =I13/I6 -> 0.03636003 | J14: =J13/J6 -> 0.03626071 | K14: =K13/K6 -> 0.036165668
B15: EBIT * (1-t) | C15: =C13*(1-'All financial statements 21-25'!C33) -> 1204.8214 | D15: =D13*(1-'All financial statements 21-25'!D33) -> 1744.8729 | E15: =E13*(1-'All financial statements 21-25'!E33) -> 1894.0253 | F15: =F13*(1-'All financial statements 21-25'!F33) -> 1836.3263 | G15: =G13*(1-24%) -> 2190.1768 | H15: =H13*(1-24%) -> 2571.7857 | I15: =I13*(1-24%) -> 2995.8273 | J15: =J13*(1-24%) -> 3122.088 | K15: =K13*(1-24%) -> 3254.0304 | L15: <--Flat tax rate of 24% based on Syscos guidance
B16: Add back: Depreciation | C16: =-C12 -> 880.933 | D16: =-D12 -> 888.677 | E16: =-E12 -> 997 | F16: =-F12 -> 1086 | G16: =-G12 -> 1060.9548 | H16: =-H12 -> 1208.995 | I16: =-I12 -> 1359.1837 | J16: =-J12 -> 1420.347 | K16: =-K12 -> 1484.2626
B17: Less: Capex | C17: ='All financial statements 21-25'!C144 -> -632.802 | D17: ='All financial statements 21-25'!D144 -> -793.325 | E17: ='All financial statements 21-25'!E144 -> -832 | F17: ='All financial statements 21-25'!F144 -> -906 | G17: =G91 -> -904.94633 | H17: =H91 -> -1031.218 | I17: =I91 -> -1159.3221 | J17: =J91 -> -1211.4916 | K17: =K91 -> -1266.0087
B18: Less: Assets from Acquisitions | C18: ='All financial statements 21-25'!C146 -> -1281.137 | D18: ='All financial statements 21-25'!D146 -> -37.384 | E18: ='All financial statements 21-25'!E146 -> -1210 | F18: ='All financial statements 21-25'!F146 -> -40 | G18: 0 | H18: -1000 | I18: -40 | J18: -1000 | K18: -40 | L18: *Very conservative assuption based on $1B cash paid for Jetro acquisition to in 2027. Not likely they will be making any large aquistions for next few years after the 1B but estimating based on historical trend to be conservative
B19: Less: Change in NWC | C19: =-'All financial statements 21-25'!C135 -> 615.998 | D19: =-'All financial statements 21-25'!D135 -> 234.534 | E19: =-'All financial statements 21-25'!E135 -> 158 | F19: =-'All financial statements 21-25'!F135 -> 576 | G19: =-G88 -> -122.09899 | H19: =-H88 -> -311.87439 | I19: =-I88 -> -316.40047 | J19: =-J88 -> -128.85182 | K19: =-K88 -> -134.65016
B20: FCFF | C20: =SUM(C15:C19) -> 787.81344 | D20: =SUM(D15:D19) -> 2037.3749 | E20: =SUM(E15:E19) -> 1007.0253 | F20: =SUM(F15:F19) -> 2552.3263 | G20: =SUM(G15:G19) -> 2224.0863 | H20: =SUM(H15:H19) -> 1437.6883 | I20: =SUM(I15:I19) -> 2839.2884 | J20: =SUM(J15:J19) -> 2202.0915 | K20: =SUM(K15:K19) -> 3297.6341
F22: 45809 | G22: 46174 | H22: 46539 | I22: 46905 | J22: 47270 | K22: 47635
B23: Total Free Cash Flow (Perpetuity) | F23: 0 | G23: =G20*(12-MONTH(F22))/12 -> 1112.0431 | H23: =H20 -> 1437.6883 | I23: =I20 -> 2839.2884 | J23: =J20 -> 2202.0915 | K23: =K20+L32 -> 79767.353
B24: Total Cash Flow (Exit Multiple) | G24: =G23 -> 1112.0431 | H24: =H20 -> 1437.6883 | I24: =I20 -> 2839.2884 | J24: =J20 -> 2202.0915 | K24: =K20+L38 -> 67159.616
B27: WACC | C27: =WACC!AI18 -> 0.061899619
B28: Tax Rate | C28: 0.24 | D28: *expected to be approximately 23.5% to 24.0% in fiscal 2026. - this statement was in the ammual report | J28: Terminal Value: Perpetuity Method
F29: Perpetuity | H29: Exit Multiple
C30: Sum of DFCFs | F30: =XNPV(C27,F23:K23,F22:K22) -> 65490.316 | H30: =XNPV(C27,G24:K24,G22:K22) -> 59630.531 | J30: Terminal Growth Rate | L30: 0.018 | M30: <-- Based on the CBO's Budget and Economic Outlook 2025 to 2035 US GDP Growth Rate
J31: FCFF 2031 | L31: =K20*(1+L30) -> 3356.9915
C32: Enterprise value | F32: =F30 -> 65490.316 | H32: =H30 -> 59630.531 | J32: Terminal Value (2030) | L32: =L31/(C27-L30) -> 76469.719
C33: Current Cash and Investments | F33: ='All financial statements 21-25'!F60 -> 1071 | H33: =F33 -> 1071
C34: Current Debt | F34: ='All financial statements 21-25'!F92+'All financial statements 21-25'!F99 -> 14494 | H34: =F34 -> 14494 | J34: Terminal Value: Exit EBITDA Multiple
C35: Net Debt | F35: =F34-F33 -> 13423 | H35: =F35 -> 13423
J36: Exit Year EBITDA (2031) | L36: =K11*(1+L30) -> 5869.6674
C37: Equity value | F37: =F32-F35 -> 52067.316 | H37: =H32-H35 -> 46207.531 | J37: Multiple | L37: 10.88 | M37: <-- Use SYY EV/EBITDA Multiple from comps tab
J38: Terminal Value (2030) | L38: =L36*L37 -> 63861.981
C39: Number of shares (million) | F39: 478.93 | H39: =F39 -> 478.93 | I39: *Mkt Cap from factset
C40: Fair value/share | F40: =F37/F39 -> 108.71592 | H40: =H37/H39 -> 96.480762
C42: Current Market Price | F42: 73.24
C43: Recommendation | F43: =IF(F40>(1.25*F42),"Strong Buy",IF(AND(F40>(F42*1.1),F40<(F42*1.25)),"Buy",IF(AND(F40>0.9*F42,F40<1.1*F40),"HOLD","SELL"))) -> Strong Buy
E45: Growth Rate
D46: =F40 -> 108.71592 | E46: 0.01 | F46: =E46+0.5% -> 0.015 | G46: =F46+0.5% -> 0.02 | H46: =G46+0.5% -> 0.025 | I46: =H46+0.5% -> 0.03
...

Sheet Sales breakdown
A1: SYY-US
A2: Sales
B3: JUN '21 | C3: JUN '22 | D3: JUN '23 | E3: JUN '24 | F3: JUN '25
A4: Total | B4: 51297.843 | C4: 68636.146 | D4: 76324.675 | E4: 78844 | F4: 81370
A5: United States Foodservice | B5: 35724.843 | C5: 48520.562 | D5: 53682.894 | E5: 55339 | F5: 56965
A6: International Foodservice | B6: 8350.638 | C6: 11787.449 | D6: 13559.61 | E6: 14561 | F6: 14905
A7: Sygma | B7: 6498.601 | C7: 7245.824 | D7: 7843.111 | E7: 7768 | F7: 8410
A8: Other | B8: 723.761 | C8: 1082.311 | D8: 1239.06 | E8: 1176 | F8: 1090
A9: Historical Segments | B9: - | C9: - | D9: - | E9: - | F9: -
A11: Growth (%)
B12: JUN '21 | C12: JUN '22 | D12: JUN '23 | E12: JUN '24 | F12: JUN '25
A13: Total | C13: =C4/B4-1 -> 0.33799283 | D13: =D4/C4-1 -> 0.11201866 | E13: =E4/D4-1 -> 0.033008002 | F13: =F4/E4-1 -> 0.032037948
A14: United States Foodservice | C14: =C5/B5-1 -> 0.35817425 | D14: =D5/C5-1 -> 0.10639473 | E14: =E5/D5-1 -> 0.03084979 | F14: =F5/E5-1 -> 0.029382533
A15: International Foodservice | C15: =C6/B6-1 -> 0.41156269 | D15: =D6/C6-1 -> 0.15034305 | E15: =E6/D6-1 -> 0.073850944 | F15: =F6/E6-1 -> 0.023624751
A16: Sygma | C16: =C7/B7-1 -> 0.11498213 | D16: =D7/C7-1 -> 0.082431895 | E16: =E7/D7-1 -> -0.0095766846 | F16: =F7/E7-1 -> 0.082646756
A17: Other | C17: =C8/B8-1 -> 0.49539834 | D17: =D8/C8-1 -> 0.14482806 | E17: =E8/D8-1 -> -0.050893419 | F17: =F8/E8-1 -> -0.073129252
A18: Historical Segments | B18: - | C18: - | D18: - | E18: - | F18: -
A20: Assumptions | B20: FY26 | C20: FY27 | D20: FY28 | E20: FY29 | F20: FY30
A21: Sysco Organic sales growth | B21: 0.04 | C21: 0.045 | D21: 0.045 | E21: 0.045 | F21: 0.045 | G21: *sales growth of approximately 3% to 5% to approximately $84 billion to $85 billion in 2026
A22: Jetro sales added ($M) | B22: 0 | C22: 8000 | D22: 16000 | E22: =D22*(1+E21) -> 16720 | F22: =E22*(1+F21) -> 17472.4 | G22: *based on management and then 4% growth

Sheet WACC
C2: Attempt 1: | W2: WACC FOR MODEL
F5: Market risk premium | Z5: Market risk premium
F6: =F41 -> 0.05 | Z6: =Z41 -> 0.05
C8: Cost | I8: Company risk premium | W8: Cost | AC8: Company risk premium
I9: =F11*F6 -> 0.0345 | AC9: =Z11*Z6 -> 0.036508621
C10: of | F10: Company Beta | N10: Capital | W10: of | Z10: Levered company Beta | AH10: Capital
F11: =F39 -> 0.69 | N11: structure | Z11: =Z39 -> 0.73017241 | AH11: structure
C12: equity | W12: equity
N13: we | AH13: we
L14: Cost of Equity | N14: =1-N21 -> 0.70128576 | AF14: Cost of Equity | AH14: =1-AH21 -> 0.47927589
L15: =I9+F18 -> 0.0745 | O15: BEFORE CONSIDERING ACQUISITION | AF15: =AC9+Z18 -> 0.076508621 | AI15: WACC FOR ACQUSITION
F17: Risk free rate | O17: WACC | Z17: Risk free rate | AI17: WACC
F18: =F38 -> 0.04 | O18: =(N14*L15)+(N21*L21) -> 0.061497604 | Z18: =Z38 -> 0.04 | AI18: =(AH14*AF15)+(AH21*AF21) -> 0.061899619
I20: Cost of Debt | L20: Net cost of debt | AC20: Cost of Debt | AF20: Net cost of debt
I21: =F40 -> 0.040223541 | L21: =I21*(1-F30) -> 0.030972126 | N21: =F42/(F42+(F43*F44)) -> 0.29871424 | AC21: =Z40 -> 0.063754545 | AF21: =AC21*(1-Z30) -> 0.048453455 | AH21: =Z42/(Z42+Z43*Z44) -> 0.52072411
N22: wd | AH22: fix
C23: Cost | W23: Cost
C25: of | W25: of
C27: debt | W27: debt
F29: Marginal tax rate | Z29: Marginal tax rate
F30: =F37 -> 0.23 | Z30: =Z37 -> 0.24
J31: YTM or risk free+ default spread
C36: KEY ASSUMPTIONS | W36: KEY ASSUMPTIONS
C37: Marginal tax rate | F37: =tax -> 0.23 | W37: Marginal tax rate | Z37: =24% -> 0.24
C38: Risk free rate(2) | F38: 0.04 | W38: Risk free rate(2) | Z38: 0.04
C39: Beta | F39: 0.69 | W39: Beta | Z39: =AH54 -> 0.73017241
C40: Cost of Debt kd | F40: =B77/F42 -> 0.040223541 | W40: Cost of Debt kd | Z40: 0.063754545
C41: Market Premium | F41: 0.05 | W41: Market Premium | Z41: 0.05
C42: Current Debt | F42: =B63+B70 -> 14494 | W42: Current Debt | Z42: =14970+22000 -> 36970
C43: Stock Price | F43: 71.16 | W43: Stock Price | Z43: 71.16
C44: Shares Outstanding (millions) | F44: 478.18 | W44: Shares Outstanding (millions) | Z44: 478.18
AG48: Levered Beta
AG49: Unlevered Beta | AH49: 0.55
AG50: Debt/equity before acqusition | AH50: =0.3/0.7 -> 0.42857143
AG51: Tax Rate | AH51: 0.24
AG52: B(levered)=B(UnL)(1+D/E(1-tax)) | AH52: =AH49/((1+(AH50*(1-AH51)))) -> 0.41487069
AG53: Debt/equity after acqusition | AH53: =0.5/0.5 -> 1
AG54: Levered Beta | AH54: =AH52*(1+AH53*(1-AH51)) -> 0.73017241
U55: August 5, 2025, Moody’s Investors Service has assigned us an unsecured debt credit rating of Baa1 and a ratings outlook of “stable." Standard & Poor’s has assigned us an unsecured debt credit rating of BBB and a ratings outlook of “stable." Fitch Ratings Inc. has assigned us an unsecured debt credit rating of BBB and a ratings outlook of “stable.
A60: Balance Sheet
...

Sheet DDM (only div)
A1: Equity Valuation: Dividend Discount Model
B2: ='Income Statement'!C8 -> JUN '25 | C2: ='Income Statement'!D8 -> JUN '24 | D2: ='Income Statement'!E8 -> JUN '23 | E2: ='Income Statement'!F8 -> JUN '22 | F2: ='Income Statement'!G8 -> JUN '21 | G2: ='Income Statement'!H8 -> JUN '20 | H2: ='Income Statement'!I8 -> JUN '19 | I2: ='Income Statement'!J8 -> JUN '18 | ... AE2: ='Income Statement'!AF8 -> JUN '96
A3: DPS | B3: ='Income Statement'!C54 -> 2.07 | C3: ='Income Statement'!D54 -> 2.01 | D3: ='Income Statement'!E54 -> 1.97 | E3: ='Income Statement'!F54 -> 1.9 | F3: ='Income Statement'!G54 -> 1.82 | G3: ='Income Statement'!H54 -> 1.74 | H3: ='Income Statement'!I54 -> 1.53 | I3: ='Income Statement'!J54 -> 1.41 | ... AE3: ='Income Statement'!AF54 -> 0.125
A4: Div Payout ratio | B4: ='Income Statement'!C55/100 -> 0.55467724 | C4: ='Income Statement'!D55/100 -> 0.51725469 | D4: ='Income Statement'!E55/100 -> 0.56728194 | E4: ='Income Statement'!F55/100 -> 0.71874409 | F4: ='Income Statement'!G55/100 -> 1.7829154 | G4: ='Income Statement'!H55/100 -> 4.1428571 | H4: ='Income Statement'!I55/100 -> 0.478125 | I4: ='Income Statement'!J55/100 -> 0.52222222 | ... AE4: ='Income Statement'!AF55/100 -> 0.32894737
A5: Return on Equity (in %) | B5: 99.078591 | C5: 101.06958 | D5: 104.40493 | E5: 92.585743 | F5: 38.665481 | G5: 11.770679 | H5: 66.843036 | I5: 58.536316 | J5: 38.985799 | K5: 21.730898 | L5: 13.047939 | M5: 17.813884 | N5: 20.096023 | O5: 23.888207 | P5: 27.002492 | Q5: 32.429464 | R5: 30.791545 | S5: 33.081715 | T5: 31.626156 | U5: 29.117952 | V5: 36.122288 | W5: 38.10193 | X5: 35.93492 | Y5: 31.775411 | Z5: 30.544209 | AA5: 28.451714 | AB5: 26.025356 | AC5: 23.561135 | AD5: 21.044676 | AE5: 19.240998
A6: Div growth rate | B6: =(B3/C3)-1 -> 0.029850746 | C6: =(C3/D3)-1 -> 0.020304569 | D6: =(D3/E3)-1 -> 0.036842105 | E6: =(E3/F3)-1 -> 0.043956044 | F6: =(F3/G3)-1 -> 0.045977011 | G6: =(G3/H3)-1 -> 0.1372549 | H6: =(H3/I3)-1 -> 0.085106383 | I6: =(I3/J3)-1 -> 0.084615385 | ... AD6: =(AD3/AE3)-1 -> 0.16
A8: ROE | B8: =B5/100 -> 0.99078591 | C8: =C5/100 -> 1.0106958 | D8: =D5/100 -> 1.0440493 | E8: =E5/100 -> 0.92585743 | F8: =F5/100 -> 0.38665481 | G8: =G5/100 -> 0.11770679 | H8: =H5/100 -> 0.66843036 | I8: =I5/100 -> 0.58536316 | ... AE8: =AE5/100 -> 0.19240998
A10: Historical Stats on Common Equity Returns (30 years)
B11: Mean | C11: Median | D11: Min | E11: Max | G11: *look at data from past 10 years
A12: =A4 -> Div Payout ratio | B12: =AVERAGE(B4:AE4) -> 0.67029618 | C12: =MEDIAN(B4:AE4) -> 0.50737107 | D12: =MIN(B4:AE4) -> 0.30681818 | E12: =MAX(B4:AE4) -> 4.1428571
A13: =A5 -> Return on Equity (in %) | B13: =AVERAGE(B8:AE8) -> 0.39445636 | C13: =MEDIAN(B8:AE8) -> 0.3120885 | D13: =MIN(B8:AE8) -> 0.11770679 | E13: =MAX(B8:AE8) -> 1.0440493
A14: =A6 -> Div growth rate | B14: =AVERAGE(B6:AE6) -> 0.10367724 | C14: =MEDIAN(B6:AE6) -> 0.085106383 | D14: =MIN(B6:AE6) -> 0.020304569 | E14: =MAX(B6:AE6) -> 0.25925926
A16: Historical Stats on Common Equity Returns (last 10 years about with out outliers)
B17: Mean | C17: Median | D17: Min | E17: Max
A18: =A12 -> Div Payout ratio | B18: =AVERAGE(B4,C4,D4,E4,H4,I4,J4,K4,M4,N4) -> 0.61258239 | C18: =MEDIAN(B4,C4,D4,E4,H4,I4,J4,K4,M4,N4) -> 0.59614097 | D18: =MIN(B4,C4,D4,E4,H4,I4,J4,K4,M4,N4) -> 0.478125 | E18: =MAX(B4,C4,D4,E4,H4,I4,J4,K4,M4,N4) -> 0.75
A19: =A13 -> Return on Equity (in %) | B19: =AVERAGE(B8,C8,D8,E8,F8,H8,I8,J8,K8,L8,M8,N8) -> 0.56071518 | C19: =MEDIAN(B8,C8,D8,E8,F8,H8,I8,J8,K8,L8,M8,N8) -> 0.48761057 | D19: =MEDIAN(C8,D8,E8,F8,G8,I8,J8,K8,L8,M8,N8,O8) -> 0.31276844 | E19: =MEDIAN(D8,E8,F8,G8,H8,J8,K8,L8,M8,N8,O8,P8) -> 0.2544535
A20: =A14 -> Div growth rate | B20: =AVERAGE(B6,C6,D6,E6,F6,H6,I6,J6,K6,L6,M6,N6) -> 0.045448173 | C20: =MEDIAN(B6,C6,D6,E6,F6,H6,I6,J6,K6,L6,M6,N6) -> 0.037112641 | D20: =MIN(B6,C6,D6,E6,F6,H6,I6,J6,K6,L6,M6,N6) -> 0.020304569 | E20: =MAX(B6,C6,D6,E6,F6,H6,I6,J6,K6,L6,M6,N6) -> 0.085106383
A22: Indicated annual div yield | B22: 2.16 | C22: *from factset
A24: Sustainable Growth Rate of Dividends
A25: CACR of DPS | B25: =_xlfn.RRI(29,AE3,B3) -> 0.10163205
A26: Sustainable Growth Rate | B26: =B27*(1-B28) -> 0.13005377
A27: ROE | B27: =B13 -> 0.39445636
A28: =A12 -> Div Payout ratio | B28: =B12 -> 0.67029618
A29: 1 yr div growth | B29: 0.064
A31: Required Rate of Return (CAPM) | B31: =B33+(B32*B34) -> 0.07746569
A32: beta | B32: =WACC!AH54 -> 0.73017241 | C32: Levered beta calculated from WACC tab
A33: risk free | B33: 0.0449 | C33: 30 Year treausre bond
A34: market premium | B34: 0.0446 | C34: *US from website: https://pages.stern.nyu.edu/~adamodar/New_Home_Page/datafile/ctryprem.html
M35: *investors who care about div and div yield this is a good investment
A36: Cost of equity | B36: 0.0765 | C36: *using cost of equity from WACC calculations
A38: Terminal growth rate | B38: 0.044 | C38: *avg growth rate over past 10 yrs
A40: g | B40: 0.03 | C40: =B40 -> 0.03 | D40: 0.04 | E40: 0.05 | F40: 0.05 | G40: 0.06 | H40: *to showcase once debt is more managable, SYY will be more aggressive with DIV growth rate
A41: t | B41: 1 | C41: 2 | D41: 3 | E41: 4 | F41: 5 | G41: 6
B42: CF1 | C42: CF2 | D42: CF3 | E42: CF4 | F42: CF5 | G42: CF6
A43: Dividends | B43: =B22*(1+B40) -> 2.2248 | C43: =B43*(1+C40) -> 2.291544 | D43: =C43*(1+D40) -> 2.3832058 | E43: =D43*(1+E40) -> 2.502366 | F43: =E43*(1+F40) -> 2.6274844 | G43: =F43*(1+G40) -> 2.7851334
A44: Terminal value | G44: =G43*(1+B38)/(B36-B38) -> 89.467055 | I44: Fair price | K44: Current price
A45: Total | B45: =SUM(B43:B44) -> 2.2248 | C45: =SUM(C43:C44) -> 2.291544 | D45: =SUM(D43:D44) -> 2.3832058 | E45: =SUM(E43:E44) -> 2.502366 | F45: =SUM(F43:F44) -> 2.6274844 | G45: =SUM(G43:G44) -> 92.252188 | I45: =NPV(B36,B45:G45) -> 68.913188 | J45: VS | K45: 73.24

Sheet Ratios
A1: Sysco Corporation (SYY)
A2: 71.16
A5: Sysco Corporation
A6: SYY 871829107 2868165 NYSE Common stock
A7: Source: FactSet Fundamentals
B8: DEC '25 | C8: DEC '24 | D8: DEC '23 | E8: DEC '22 | F8: DEC '21 | J8: DEC '25 | K8: DEC '24 | L8: DEC '23 | M8: DEC '22 | N8: DEC '21 | Q8: Sysco | R8: USFD | S8: PFGC | T8: UNFI
P9: Market Cap (M) | Q9: 34080.7 | R9: 19828.93 | S9: 13917.88 | T9: 2724.12
P10: Revenue (M) | Q10: 76324.68 | R10: 35597 | S10: 57254.7 | T10: 30272
A11: Profitability | I11: Profitability | P11: Ratios
A12: Gross Margin | B12: 18.35 | C12: 18.31 | D12: 18.28 | E12: 17.92 | F12: 17.8 | I12: Gross Margin | J12: 18.35 | K12: 18.31 | L12: 18.28 | M12: 17.92 | N12: 17.8 | P12: Profitability
P13: P/S | Q13: =Q9/Q10 -> 0.44652267 | R13: =R9/R10 -> 0.55703936 | S13: =S9/S10 -> 0.24308712 | T13: =T9/T10 -> 0.089988108
A14: SG&A to Sales | B14: 14.15 | C14: 14.04 | D14: 14.05 | E14: 14.16 | F14: 14.5 | I14: Operating Margin | J14: 4.2 | K14: 4.28 | L14: 4.23 | M14: 3.76 | N14: 3.31 | P14: Gross Margin | Q14: =J12 -> 18.35 | R14: 17.41 | S14: 10.69 | T14: 12.47
A15: Operating Margin | B15: 4.2 | C15: 4.28 | D15: 4.23 | E15: 3.76 | F15: 3.31 | I15: Net Margin | J15: 2.17 | K15: 2.4 | L15: 2.69 | M15: 1.93 | N15: 1.29 | P15: Operating Margin | Q15: =J14 -> 4.2 | R15: 3.37 | S15: 1.36 | T15: 0.78
A16: Pretax Margin | B16: 2.84 | C16: 3.14 | D16: 3.51 | E16: 2.45 | F16: 1.59 | I16: Return on Assets | J16: 6.85 | K16: 7.72 | L16: 8.89 | M16: 6.53 | N16: 3.58 | P16: Net Margin | Q16: =J15 -> 2.17 | R16: 1.71 | S16: 0.52 | T16: -0.27
A17: Net Margin | B17: 2.17 | C17: 2.4 | D17: 2.69 | E17: 1.93 | F17: 1.29 | I17: Return on Equity | J17: 83.64 | K17: 87.49 | L17: 108.42 | M17: 106.87 | N17: 59.33 | P17: Return on Assets | Q17: =J16 -> 6.85 | R17: 4.81 | S17: 1.93 | T17: -1.13
A18: Free Cash Flow Margin | B18: 2.12 | C18: 2.25 | D18: 3.08 | E18: 1.57 | F18: 1.41 | I18: Return on Invested Capital | J18: 11.86 | K18: 13.09 | L18: 15.09 | M18: 11.41 | N18: 5.83 | P18: Return on Equity | Q18: =J17 -> 83.64 | R18: 15.3 | S18: 7.75 | T18: -5.4
A19: Free Cash Flow Conversion Ratio | B19: 40.9 | C19: 41.78 | D19: 66.59 | E19: 12.73 | F19: -10.71 | I19: Operating Efficiency | P19: Return on Invested Capital | Q19: =J18 -> 11.86 | R19: 7.02 | S19: 2.86 | T19: 11.43
A20: Capex To Sales | B20: 1.06 | C20: 1.02 | D20: 1.07 | E20: 1.03 | F20: 0.8 | I20: Days of Sales Outstanding | J20: 24.04 | K20: 24.05 | L20: 24.09 | M20: 22.95 | N20: 21.7 | P20: Operating Efficiency
A21: Return on Assets | B21: 6.85 | C21: 7.72 | D21: 8.89 | E21: 6.53 | F21: 3.58 | I21: Days of Payables Outstanding | J21: 31.8 | K21: 31.95 | L21: 32.12 | M21: 31.26 | N21: 30.72 | P21: Days of Sales Outstanding | Q21: =J20 -> 24.04 | R21: 20.5 | S21: 15.24 | T21: 11.91
A22: Return on Equity | B22: 83.64 | C22: 87.49 | D22: 108.42 | E22: 106.87 | F22: 59.33 | I22: Net Operating Cycle | J22: 20.12 | K22: 19.2 | L22: 19.01 | M22: 18.21 | N22: 17.36 | P22: Days of Payables Outstanding | Q22: =J21 -> 31.8 | R22: 26.15 | S22: 19.27 | T22: 24.25
A23: Return on Common Equity | B23: 83.64 | C23: 87.49 | D23: 108.42 | E23: 106.87 | F23: 59.33 | I23: Leverage | P23: Net Operating Cycle | Q23: =J22 -> 20.12 | R23: 13.05 | S23: 21.39 | T23: 16.4
A24: Return on Total Capital | B24: 21.01 | C24: 22.14 | D24: 22.88 | E24: 20.98 | F24: 13.82 | I24: Total Debt/Total Assets (%) | J24: 55.07 | K24: 54.07 | L24: 52.42 | M24: 53.38 | N24: 55.27 | P24: Leverage
A25: Return on Invested Capital | B25: 11.86 | C25: 13.09 | D25: 15.09 | E25: 11.41 | F25: 5.83 | P25: Total Debt/Total Assets (%) | Q25: =J24 -> 55.07 | R25: 39.99 | S25: 43.32 | T25: 45.08
A26: Cash Flow Return on Invested Capital | B26: 17.3 | C26: 17.82 | D26: 23.34 | E26: 15.41 | F26: 9.98 | P26: Coverage
A27: Valuation | P27: (EBITDA-Capex)/Interest Expense | Q27: =B103 -> 6.32 | R27: 5.88 | S27: 2.94 | T27: 2.62
A28: Enterprise Value/EBIT | B28: 14.3 | C28: 13.75 | D28: 14.61 | E28: 19.4 | F28: 24.21 | P28: Net Debt/(EBITDA-Capex) | Q28: =B89 -> 3.73 | R28: 4.11 | S28: 6.76 | T28: 8.81
A29: Enterprise Value/EBITDA | B29: 10.88 | C29: 10.53 | D29: 11.36 | E29: 14.7 | F29: 16.92
A30: Enterprise Value/Sales | B30: 0.6 | C30: 0.59 | D30: 0.62 | E30: 0.73 | F30: 0.8
A31: Total Debt/Enterprise Value | B31: 0.3 | C31: 0.29 | D31: 0.27 | E31: 0.22 | F31: 0.24
A32: Per Share
A33: Sales per Share | B33: 171.94 | C33: 163.49 | D33: 153.21 | E33: 144.23 | F33: 118.04
A34: EBIT (Operating Income) per Share | B34: 7.22 | C34: 6.99 | D34: 6.48 | E34: 5.42 | F34: 3.9
A35: EPS (recurring) | B35: 4.44 | C35: 4.23 | D35: 4.29 | E35: 2.98 | F35: 2.38
A36: EPS (basic) | B36: 3.73 | C36: 3.91 | D36: 4.11 | E36: 2.79 | F36: 1.53
A37: EPS (diluted) | B37: 3.72 | C37: 3.89 | D37: 4.1 | E37: 2.77 | F37: 1.52
A38: Dividends per Share | B38: 2.13 | C38: 2.03 | D38: 1.99 | E38: 1.94 | F38: 1.86
A39: Dividend Payout Ratio (%) | B39: 57.29 | C39: 52.15 | D39: 48.55 | E39: 69.92 | F39: 122.06
A40: Book Value per Share | B40: 4.77 | C40: 4.11 | D40: 4.77 | E40: 2.83 | F40: 2.41
A41: Tangible Book Value per Share | B41: -8.44 | C41: -8.68 | D41: -7.99 | E41: -7.99 | F41: -8.09
A42: Cash Flow per Share | B42: 5.46 | C42: 5.34 | D42: 6.36 | E42: 3.76 | F42: 2.61
...

Sheet Comparables
C3: EPS | D3: EBITDA | E3: EBIT | F3: Sysco Comparable Valuation
B4: Company | C4: P/E | D4: EV/EBITDA | E4: EV/EBIT | G4: EV/EBIT | H4: EV/EBITDA | I4: P/E
B5: Comparable Markets | F5: 2025 | G5: ='Income Statement'!B58 -> 3470 | H5: ='Income Statement'!B57 -> 4560 | I5: ='Income Statement'!B50*'Income Statement'!B51 -> 1787.1998 | J5: annual report says adjusted EPS of 4.46 which is higher
B6: US Food Holding Corp (USFD) | C6: ='Comparable Co Statements '!A2/'Comparable Co Statements '!B34 -> 30.581633 | D6: ='Comparable Co Statements '!B26 -> 12.44 | E6: ='Comparable Co Statements '!B25 -> 16.76 | F6: Implied Enterprise Value | G6: =G5*E10 -> 71724.9 | H6: =H5*D10 -> 56726.4
B7: Performance Food Group Company (PFGC) | C7: ='Comparable Co Statements '!H2/'Comparable Co Statements '!I34 -> 38.186364 | D7: ='Comparable Co Statements '!I26 -> 12.85 | E7: ='Comparable Co Statements '!I25 -> 24.05 | F7: Debt | G7: ='Balance Sheet'!B46+'Balance Sheet'!B53 -> 14494 | H7: =G7 -> 14494
B8: United Natural Food Inc (UNFI) | C8: ='Comparable Co Statements '!P2/'Comparable Co Statements '!P34 -> 0 | D8: ='Comparable Co Statements '!P26 -> 9.09 | E8: ='Comparable Co Statements '!P25 -> 20.67
B9: Mean | C9: =AVERAGE(C6:C8) -> 22.922665 | D9: =AVERAGE(D6:D8) -> 11.46 | E9: =AVERAGE(E6:E8) -> 20.493333 | F9: Cash | G9: ='Balance Sheet'!B85 -> 41 | H9: ='Balance Sheet'!B85 -> 41 | J9: why is cash for fisical vs calendar year so different
B10: Median | C10: =MEDIAN(C6:C8) -> 30.581633 | D10: =MEDIAN(D6:D8) -> 12.44 | E10: =MEDIAN(E6:E8) -> 20.67 | F10: Implied equity value | G10: =G6-G7+G9 -> 57271.9 | H10: =H6-H7+H9 -> 42273.4 | I10: =I5*C10 -> 54655.487
B11: Target | F11: Number of shares (million) | G11: ='Income Statement'!B51 -> 480.66263 | H11: =G11 -> 480.66263 | I11: =H11 -> 480.66263
B12: Sysco (SYY) | C12: ='Income Statement'!A2/'Income Statement'!B50 -> 19.181324 | D12: =#REF! -> #REF! | E12: =#REF! -> #REF! | F12: Value per share | G12: =G10/G11 -> 119.15197 | H12: =H10/H11 -> 87.948173 | I12: =I10/I11 -> 113.70863

Sheet Sales Charts
C2: Fiscal Year Sales (in millions)
B3: Segment | C3: 2025 | D3: 2024 | E3: 2023
B4: United States | C4: 66073 | D4: 63931 | E4: 62404
B5: Canada | C5: 6113 | D5: 5993 | E5: 5828
B6: United Kingdom | C6: 4081 | D6: 3760 | E6: 3340
B7: France | C7: 1714 | D7: 1712 | E7: 1591
B8: Other | C8: 3389 | D8: 3448 | E8: 3162
B9: Total | C9: =SUM(C4:C8) -> 81370 | D9: =SUM(D4:D8) -> 78844 | E9: =SUM(E4:E8) -> 76325
H10: FY 2028
B12: Segment | C12: 2025 Total Sales by Segment
B13: United States | C13: =C4/$C$9 -> 0.81200688
B14: Canada | C14: =C5/$C$9 -> 0.075125968
B15: United Kingdom | C15: =C6/$C$9 -> 0.050153619
B16: France | C16: =C7/$C$9 -> 0.021064274
B17: Other | C17: =C8/$C$9 -> 0.041649256

Sheet All financial statements 21-25
A1: Sysco Corporation (SYY)
A2: $71.16
A4: Sysco Corporation
A5: SYY 871829107 2868165 NYSE Common stock
A6: Source: FactSet Fundamentals
A7: INCOME STATEMENT
B8: JUN '21 | C8: JUN '22 | D8: JUN '23 | E8: JUN '24 | F8: JUN '25
A10: Sales | B10: 51297.843 | C10: 68636.146 | D10: 76324.675 | E10: 78844 | F10: 81370
A11: Cost of Goods Sold (COGS) incl. D&A | B11: 42573.402 | C11: 56421.622 | D11: 62474.678 | E11: 65092 | F11: 67332
A12: COGS excluding D&A | B12: 41720.996 | C12: 55539.97 | D12: 61585.505 | E12: 64098 | F12: 66246
A13: Depreciation & Amortization Expense | B13: 852.406 | C13: 881.652 | D13: 889.173 | E13: 994 | F13: 1086
A14: Depreciation | B14: 748.906 | C14: 748.752 | D14: 762.873 | E14: 852 | F14: 939
A15: Amortization of Intangibles | B15: 103.5 | C15: 132.9 | D15: 126.3 | E15: 142 | F15: 147
A16: Gross Income | B16: 8724.441 | C16: 12214.524 | D16: 13849.997 | E16: 13752 | F16: 14038
A17: SG&A Expense | B17: 7133.31 | C17: 9784.725 | D17: 10708.566 | E17: 10270 | F17: 10526
A18: Other SG&A | B18: 7133.31 | C18: 9784.725 | D18: 10708.566 | E18: 10270 | F18: 10526
A19: EBIT (Operating Income) | B19: 1591.131 | C19: 2429.799 | D19: 3141.431 | E19: 3482 | F19: 3512
A20: Nonoperating Income - Net | B20: -4.29 | C20: 71.821 | D20: -267.023 | E20: -42 | F20: -33
A21: Other Income (Expense) | B21: -4.29 | C21: 71.821 | D21: -267.023 | E21: -42 | F21: -33
... A24: Unusual Expense - Net | B24: 497.074 | C24: 284.583 | D24: 88.753 | E24: 297 | F24: 476
A25: Impairments | B25: 0 | F25: 92
A26: Goodwill | B26: 0 | C26: 0 | D26: 0 | E26: 0 | F26: 92
A27: Restructuring Expense | B27: 133.727 | C27: 142.705 | D27: 73.854 | E27: 279 | F27: 343
A28: Unrealized Valuation Gain/Loss | B28: -69.45 | C28: -26.275 | D28: -14.899 | E28: -18 | F28: -41
A29: Hedges/Derivatives | B29: -69.45 | C29: -26.275 | D29: -14.899 | E29: -18 | F29: -41
A30: Excpl Chrgs - Others | B30: 293.897 | C30: 115.603 | D30: 0
A31: Restructuring of Debt | B31: 293.897 | C31: 115.603 | D31: 0
A32: Pretax Income | B32: 584.728 | C32: 1746.773 | D32: 2285.355 | E32: 2565 | F32: 2415
A33: EFFECTIVE TAX RATE | B33: =B34/B32 -> 0.1034994 | C33: =C34/C32 -> 0.22212674 | D33: =D34/D32 -> 0.225449 | E33: =E34/E32 -> 0.23781676 | F33: =F34/F32 -> 0.24306418
A34: Income Taxes | B34: 60.519 | C34: 388.005 | D34: 515.231 | E34: 610 | F34: 587
A35: Income Taxes - Current Domestic | B35: 218.383 | C35: 452.459 | D35: 531.665 | E35: 584 | F35: 602
A36: Income Taxes - Deferred Domestic | B36: -157.864 | C36: -64.454 | D36: -16.434 | E36: 26 | F36: -15
A37: Consolidated Net Income | B37: 524.209 | C37: 1358.768 | D37: 1770.124 | E37: 1955 | F37: 1828
A38: Net Income | B38: 524.209 | C38: 1358.768 | D38: 1770.124 | E38: 1955 | F38: 1828
A39: Net Income available to Common | B39: 524.209 | C39: 1358.768 | D39: 1770.124 | E39: 1955 | F39: 1828
A40: Per Share
A41: EPS (recurring) | B41: 1.698281 | C41: 3.031048 | D41: 3.594624 | E41: 4.299179 | F41: 4.412182
A42: EPS (basic) | B42: 1.0265 | C42: 2.661 | D42: 3.4889 | E42: 3.9003 | F42: 3.7448
A43: Basic Shares Outstanding | B43: 510.6964 | C43: 510.63065 | D43: 507.36291 | E43: 501.23842 | F43: 488.14433
A44: Total Shares Outstanding | B44: 511.35789 | C44: 508.64336 | D44: 505.11207 | E44: 491.75822 | F44: 477.49624
...

Sheet Statement of Cash Flows
A1: Sysco Corporation (SYY)
A2: 71.38
A5: Sysco Corporation
A6: SYY 871829107 2868165 NYSE Common stock
A7: Source: FactSet Fundamentals
B8: DEC '25 | C8: JUN '25 | D8: JUN '24 | E8: JUN '23 | F8: JUN '22 | G8: JUN '21 | H8: JUN '20 | I8: JUN '19 | J8: JUN '18 | K8: JUN '17 | L8: JUN '16 | M8: JUN '15 | N8: JUN '14 | O8: JUN '13 | P8: JUN '12 | Q8: JUN '11 | R8: JUN '10 | S8: JUN '09 | T8: JUN '08 | U8: JUN '07 | V8: JUN '06 | W8: JUN '05 | X8: JUN '04 | Y8: JUN '03 | Z8: JUN '02 | AA8: JUN '01 | AB8: JUN '00 | AC8: JUN '99 | AD8: JUN '98 | AE8: JUN '97 | AF8: JUN '96
B9: LTM
J10: Restate | K10: Restate
A11: Operating Activities
A12: Net Income / Starting Line | B12: 1798 | C12: 1828 | D12: 1955 | E12: 1770.1 | F12: 1358.8 | G12: 524.2 | H12: 215.5 | I12: 1674.3 | J12: 1430.8 | K12: 1142.5 | L12: 949.6 | M12: 686.8 | N12: 931.5 | O12: 992.4 | P12: 1121.6 | Q12: 1152 | R12: 1180 | S12: 1055.9 | T12: 1106.2 | U12: 1001.1 | V12: 855.3 | W12: 961.5 | X12: 907.2 | Y12: 778.3 | Z12: 679.8 | AA12: 596.9 | AB12: 453.6 | AC12: 362.3 | AD12: 324.8 | AE12: 302.5 | AF12: 276.9
A13: Depreciation, Depletion & Amortization | B13: 1092 | C13: 1086 | D13: 997 | E13: 888.7 | F13: 880.9 | G13: 851.8 | H13: 914.1 | I13: 763.9 | J13: 765.5 | K13: 902 | L13: 662.7 | M13: 553 | N13: 556.1 | O13: 512.5 | P13: 416.9 | Q13: 402.6 | R13: 390 | S13: 382.3 | T13: 372.5 | U13: 362.6 | V13: 345.1 | W13: 316.7 | X13: 283.6 | Y13: 273.1 | Z13: 278.3 | AA13: 248.2 | AB13: 220.7 | AC13: 205 | AD13: 181.2 | AE13: 160.3 | AF13: 144.7
A14: Depreciation and Depletion | X14: 273 | Y14: 273.1 | Z14: 278.3 | AA14: 248.2 | AB14: 220.7 | AC14: 205 | AD14: 181.2 | AE14: 160.3 | AF14: 144.7
A15: Amortization of Intangible Assets | X15: 10.6 | AF15: 0
A16: Deferred Taxes & Investment Tax Credit | B16: -4 | C16: -13 | D16: 27 | E16: -16.4 | F16: -64.5 | G16: -157.9 | H16: -191.3 | I16: -126.7 | J16: 187.9 | K16: -51.8 | L16: 93.9 | M16: -4.7 | N16: -30.7 | O16: -28.1 | P16: -177.9 | Q16: -165.2 | R16: -121.9 | S16: -294.2 | T16: 643.5 | U16: 546 | V16: 482.1 | W16: 554.9 | X16: 608.2 | Y16: 481.3 | Z16: 263.5 | AA16: 6.2 | AB16: -25.5 | AC16: 5.7 | AD16: -15.1 | AE16: 11.1 | AF16: 16.1
A17: Deferred Taxes | B17: -4 | C17: -13 | D17: 27 | E17: -16.4 | F17: -64.5 | G17: -157.9 | H17: -191.3 | I17: -126.7 | J17: 187.9 | K17: -51.8 | L17: 93.9 | M17: -4.7 | N17: -30.7 | O17: -28.1 | P17: -177.9 | Q17: -165.2 | R17: -121.9 | S17: -294.2 | T17: 643.5 | U17: 546 | V17: 482.1 | W17: 554.9 | X17: 608.2 | Y17: 481.3 | Z17: 263.5 | AA17: 6.2 | AB17: -25.5 | AC17: 5.7 | AD17: -15.1 | AE17: 11.1 | AF17: 16.1
A18: Other Funds | B18: 229 | C18: 185 | D18: 168 | E18: 459.8 | F18: 232 | G18: 269.3 | H18: 727.7 | I18: 119.8 | J18: 200.9 | K18: 143.1 | L18: 356 | M18: 95.5 | N18: 111.6 | O18: 107.9 | P18: 102.7 | Q18: 92.4 | R18: 103.8 | S18: 127.1 | T18: 110.1 | U18: 119.9 | V18: 137.4 | W18: 18.6 | X18: 27.4 | Y18: 27.1 | Z18: 25.9 | AA18: 21.7 | AB18: 27.1 | AC18: 26.2 | AD18: 23 | AE18: 21.6 | AF18: 1.9
A19: Funds from Operations | B19: 3115 | C19: 3086 | D19: 3147 | E19: 3102.1 | F19: 2407.3 | G19: 1487.5 | H19: 1666 | I19: 2431.2 | J19: 2585 | K19: 2135.8 | L19: 2062.2 | M19: 1330.6 | N19: 1568.6 | O19: 1584.7 | P19: 1463.3 | Q19: 1481.8 | R19: 1551.9 | S19: 1271.2 | T19: 2232.2 | U19: 2029.5 | V19: 1819.9 | W19: 1851.6 | X19: 1826.3 | Y19: 1559.9 | Z19: 1247.4 | AA19: 873.1 | AB19: 675.8 | AC19: 599.1 | AD19: 513.9 | AE19: 495.5 | AF19: 439.6
A20: Changes in Working Capital | B20: -492 | C20: -576 | D20: -158 | E20: -234.5 | F20: -616 | G20: 416.4 | H20: -47.3 | I20: -20 | J20: -429.6 | K20: 103.6 | L20: -129.1 | M20: 224.9 | N20: -75.7 | O20: -73.1 | P20: -59.2 | Q20: -390.3 | R20: -666.5 | S20: 311.1 | T20: -636.1 | U20: -626.5 | V20: -696.1 | W20: -659.8 | X20: -636.8 | Y20: -187.1 | Z20: -162.5 | AA20: 82.1 | AB20: 32.9 | AC20: -13.8 | AD20: -156.2 | AE20: 2.6 | AF20: -89.2
A21: Receivables | B21: -224 | C21: -206 | D21: -110 | E21: -270.6 | F21: -971.2 | G21: -662.3 | H21: 915.7 | I21: -203.5 | J21: -37.5 | K21: 20.5 | L21: -27.3 | M21: -11.7 | N21: -236.3 | O21: -193.8 | P21: -106.8 | Q21: -252.6 | R21: -166.4 | S21: 188.7 | T21: -128 | U21: -134.2 | V21: -162.6 | W21: -72.8 | X21: -177.1 | Y21: -218.2 | Z21: -32.4 | AA21: -83.9 | AB21: -118.6 | AC21: -145 | AD21: -162.3 | AE21: -40.2 | AF21: -123.7
A22: Inventories | B22: -124 | C22: -330 | D22: -70 | E22: -22.2 | F22: -708.6 | G22: -551.4 | H22: 114.6 | I22: -114.7 | J22: -89.7 | K22: -113.6 | L22: 66.9 | M22: -125.2 | N22: -195.8 | O22: -180.3 | P22: -99.2 | Q22: -254.7 | R22: -106.2 | S22: 177.6 | T22: -110.9 | U22: -95.9 | V22: -119.4 | W22: -35 | X22: -162.5 | Y22: -70 | Z22: -17.8 | AA22: -54.1 | AB22: -56.9 | AC22: -61.5 | AD22: -48.5 | AE22: -6.9 | AF22: -56.1
A23: Accounts Payable | B23: 99 | C23: 143 | D23: 104 | E23: 195.6 | F23: 810.5 | G23: 1459.2 | H23: -834.1 | I23: 246.4 | J23: 76.9 | K23: 322.8 | L23: 23.9 | M23: 72.5 | N23: 392.7 | O23: 207.2 | P23: 30.3 | Q23: 187.4 | R23: 154.8 | S23: -192.7 | T23: 54.5 | U23: 85.4 | V23: 49.8 | W23: 28.1 | X23: 95.9 | Y23: 237.4 | Z23: -0.4 | AA23: 33.4 | AB23: 105.8 | AC23: 164.1 | AD23: 14.1 | AE23: 43.1 | AF23: 70.7
A24: Income Taxes Payable | B24: -94 | C24: -62 | D24: 13 | E24: 92 | F24: -9.8 | G24: 119 | H24: -102.7 | I24: 4.9 | J24: -10.7 | K24: -74.6 | L24: 231.5 | M24: -32.8 | N24: -18.7 | O24: -38 | P24: 71.3 | Q24: -44.2 | R24: -296.5 | S24: 325.5 | T24: -509.8 | U24: -492 | V24: -545.6 | W24: -438.8 | X24: -392.2 | Y24: -33.1 | Z24: -81.7 | AA24: 106 | AB24: 16.3 | AC24: -19.4 | AD24: 7.8 | AE24: -5.6 | AF24: 13
A25: Other Accruals | B25: 42 | C25: -14 | D25: -12 | E25: 22.4 | F25: 423.4 | G25: 167.2 | H25: -139.9 | I25: 137.5 | J25: 47.1 | K25: -4.5 | L25: -178.3 | M25: 464.4 | N25: 55.8 | O25: 76.5 | P25: 41.4 | Q25: -43.3 | R25: 58 | S25: -120.3 | T25: -22.7 | U25: 132.9 | V25: 29.2 | W25: -32.7 | X25: 26.5 | Y25: -85.3 | Z25: -23.4 | AA25: 86.6 | AB25: 128.2 | AC25: 82 | AD25: 50.9 | AE25: 27.5 | AF25: 6.6
A26: Other Assets/Liabilities | B26: -191 | C26: -107 | D26: -83 | E26: -251.6 | F26: -160.3 | G26: -115.3 | H26: -0.9 | I26: -90.8 | J26: -415.8 | K26: -46.9 | L26: -245.8 | M26: -142.2 | N26: -73.5 | O26: 55.2 | P26: 3.9 | Q26: 17.3 | R26: -310.2 | S26: -67.7 | T26: 80.9 | U26: -122.8 | V26: 52.6 | W26: -108.6 | X26: -27.4 | Y26: -17.9 | Z26: -6.8 | AA26: -5.8 | AB26: -41.8 | AC26: -34.1 | AD26: -18.2 | AE26: -15.3 | AF26: 0.2
A27: Net Operating Cash Flow | B27: 2623 | C27: 2510 | D27: 2989 | E27: 2867.6 | F27: 1791.3 | G27: 1903.8 | H27: 1618.7 | I27: 2411.2 | J27: 2155.4 | K27: 2239.4 | L27: 1933.1 | M27: 1555.5 | N27: 1492.8 | O27: 1511.6 | P27: 1404.2 | Q27: 1091.5 | R27: 885.4 | S27: 1582.3 | T27: 1596.1 | U27: 1402.9 | V27: 1123.8 | W27: 1191.8 | X27: 1189.5 | Y27: 1372.8 | Z27: 1085 | AA27: 955.2 | AB27: 708.7 | AC27: 585.3 | AD27: 357.8 | AE27: 498.1 | AF27: 350.4
A28: Investing Activities
A29: Capital Expenditures | B29: -873 | C29: -906 | D29: -832 | E29: -793.3 | F29: -632.8 | G29: -470.7 | H29: -720.4 | I29: -692.4 | J29: -687.8 | K29: -686.4 | L29: -527.3 | M29: -542.8 | N29: -523.2 | O29: -511.9 | P29: -784.5 | Q29: -636.4 | R29: -594.6 | S29: -464.6 | T29: -516 | U29: -603.2 | V29: -514.8 | W29: -390.2 | X29: -530.1 | Y29: -435.6 | Z29: -416.4 | AA29: -341.1 | AB29: -266.4 | AC29: -286.7 | AD29: -259.4 | AE29: -210.9 | AF29: -235.9
A30: Capital Expenditures (Fixed Assets) | B30: -873 | C30: -906 | D30: -832 | E30: -793.3 | F30: -632.8 | G30: -470.7 | H30: -720.4 | I30: -692.4 | J30: -687.8 | K30: -686.4 | L30: -527.3 | M30: -542.8 | N30: -523.2 | O30: -511.9 | P30: -784.5 | Q30: -636.4 | R30: -594.6 | S30: -464.6 | T30: -516 | U30: -603.2 | V30: -514.8 | W30: -390.2 | X30: -530.1 | Y30: -435.6 | Z30: -416.4 | AA30: -341.1 | AB30: -266.4 | AC30: -286.7 | AD30: -259.4 | AE30: -210.9 | AF30: -235.9
A31: Net Assets from Acquisitions | B31: -133 | C31: -40 | D31: -1210 | E31: -37.4 | F31: -1281.1 | G31: 0 | H31: -142.8 | I31: -106.6 | J31: -248.1 | K31: -2921.8 | L31: -219.2 | M31: -115.9 | N31: -79.3 | O31: -397.4 | P31: -110.6 | Q31: -101.1 | R31: -29.3 | S31: -218.1 | T31: -55.3 | U31: -59.3 | V31: -114.4 | W31: -115.6 | X31: -79.2 | Y31: -209 | Z31: -234.6 | AA31: -10.4 | AB31: -211.9 | AC31: 0 | AD31: -84.5 | AE31: -5.3 | AF31: 0
A32: Sale of Fixed Assets & Businesses | B32: 150 | C32: 214 | D32: 79 | E32: 42.1 | F32: 24.1 | G32: 59.1 | H32: 28.7 | I32: 170.8 | J32: 22.3 | K32: 23.7 | L32: 23.5 | M32: 24.5 | N32: 25.8 | O32: 15.5 | P32: 8.2 | Q32: 19.1 | R32: 21.7 | S32: 25.2 | T32: 13.3 | U32: 16 | V32: 22.7 | W32: 25.5 | X32: 15.9 | Y32: 14.6 | Z32: 20.7 | AA32: 12.8 | AB32: 18.9 | AC32: 25 | AD32: 8.3 | AE32: 2.8 | AF32: 11
A33: Purchase/Sale of Investments | B33: 8 | C33: -3 | D33: -4 | E33: -4.6 | F33: -2.7 | G33: -17.2 | H33: 9.1 | I33: -116.4 | J33: 0 | K33: 0 | L33: 168.3 | M33: -20.1 | N33: -0.1 | O33: -18.1 | P33: -16.7 | Q33: 39 | R33: -54.1 | S33: -1.3 | T33: 2.3 | U33: -2.2 | V33: -2.2 | W33: 66.9 | X33: 0 | Y33: 0 | Z33: 0 | AA33: 0 | AB33: 0 | AC33: 0 | AD33: 0 | AE33: 0 | AF33: 0
A34: Purchase of Investments | B34: 16 | C34: 32 | D34: 33 | E34: 16.2 | F34: 19.3 | G34: 53.1 | H34: 11.4 | I34: 116.4 | J34: 0 | K34: 0 | L34: 0 | M34: 20.1 | N34: 0.1 | O34: 18.1 | P34: 16.7 | Q34: 0 | R34: 115.7 | S34: 1.3 | T34: 0 | U34: 2.2 | V34: 2.2 | W34: 0 | X34: 0 | Y34: 0 | Z34: 0 | AA34: 0 | AB34: 0 | AC34: 0 | AD34: 0 | AE34: 0 | AF34: 0
A35: Sale/Maturity of Investments | B35: 24 | C35: 29 | D35: 29 | E35: 11.6 | F35: 16.6 | G35: 36 | H35: 20.5 | I35: 0 | J35: 0 | K35: 0 | L35: 168.3 | M35: 0 | N35: 0 | O35: 0 | P35: 0 | Q35: 39 | R35: 61.6 | S35: 0 | T35: 2.3 | U35: 0 | V35: 0 | W35: 66.9 | X35: 0 | Y35: 0 | Z35: 0 | AA35: 0 | AB35: 0 | AC35: 0 | AD35: 0 | AE35: 0 | AF35: 0
A36: Other Funds | B36: 35 | C36: 18 | D36: 5 | E36: 8.5 | F36: 14.3 | G36: 0 | H36: 69.1 | I36: 1.8 | J36: 3.3 | K36: 0 | L36: -46 | M36: 0 | N36: 0 | O36: 0 | P36: 0 | Q36: 0 | R36: 0 | S36: 0 | T36: 0 | U36: 0 | V36: 0 | W36: 0 | X36: -90.3 | Y36: -51.8 | Z36: 0 | AA36: 0 | AB36: 0 | AC36: 0 | AD36: 0 | AE36: 0 | AF36: 0
A37: Other Uses | B37: 0 | C37: 0 | D37: 0 | E37: 0 | F37: 0 | G37: 0 | H37: 0 | I37: 0 | J37: 0 | K37: 0 | L37: -103.5 | M37: 0 | N37: 0 | O37: 0 | P37: 0 | Q37: 0 | R37: 0 | S37: 0 | T37: 0 | U37: 0 | V37: 0 | W37: 0 | X37: -90.3 | Y37: -51.8 | Z37: 0 | AA37: 0 | AB37: 0 | AC37: 0 | AD37: 0 | AE37: 0 | AF37: 0
A38: Other Sources | B38: 35 | C38: 18 | D38: 5 | E38: 8.5 | F38: 14.3 | G38: 0 | H38: 69.1 | I38: 1.8 | J38: 3.3 | K38: 0 | L38: 57.5 | M38: 0 | N38: 0 | O38: 0 | P38: 0 | Q38: 0 | R38: 0 | S38: 0 | T38: 0 | U38: 0 | V38: 0 | W38: 0 | X38: 0 | Y38: 0 | Z38: 0 | AA38: 0 | AB38: 0 | AC38: 0 | AD38: 0 | AE38: 0 | AF38: 0
A39: Net Investing Cash Flow | B39: -813 | C39: -717 | D39: -1962 | E39: -784.6 | F39: -1878.2 | G39: -428.7 | H39: -756.3 | I39: -742.9 | J39: -910.4 | K39: -3584.5 | L39: -600.8 | M39: -654.3 | N39: -576.8 | O39: -911.9 | P39: -903.6 | Q39: -679.6 | R39: -656.3 | S39: -658.7 | T39: -555.6 | U39: -648.7 | V39: -608.7 | W39: -413.4 | X39: -683.8 | Y39: -681.8 | Z39: -630.3 | AA39: -338.8 | AB39: -459.4 | AC39: -261.7 | AD39: -335.5 | AE39: -213.4 | AF39: -224.9
A40: Financing Activities
A41: Cash Dividends Paid | B41: -1015 | C41: -1000 | D41: -1008 | E41: -996 | F41: -958.9 | G41: -917.6 | H41: -856.3 | I41: -775.4 | J41: -722.2 | K41: -698.6 | L41: -698.9 | M41: -695.3 | N41: -667.2 | O41: -648.3 | P41: -622.9 | Q41: -597.1 | R41: -579.8 | S41: -548.2 | T41: -497.5 | U41: -445.4 | V41: -397.5 | W41: -357.3 | X41: -309.5 | Y41: -261.9 | Z41: -213.3 | AA41: -173.7 | AB41: -145.4 | AC41: -126.7 | AD41: -110.9 | AE41: -99.6 | AF41: -87.7
A42: Common Dividends | B42: -1015 | C42: -1000 | D42: -1008 | E42: -996 | F42: -958.9 | G42: -917.6 | H42: -856.3 | I42: -775.4 | J42: -722.2 | K42: -698.6 | L42: -698.9 | M42: -695.3 | N42: -667.2 | O42: -648.3 | P42: -622.9 | Q42: -597.1 | R42: -579.8 | S42: -548.2 | T42: -497.5 | U42: -445.4 | V42: -397.5 | W42: -357.3 | X42: -309.5 | Y42: -261.9 | Z42: -213.3 | AA42: -173.7 | AB42: -145.4 | AC42: -126.7 | AD42: -110.9 | AE42: -99.6 | AF42: -87.7
...

Sheet Income Statement
A1: Sysco Corporation (SYY)
A2: $71.32
A5: Sysco Corporation
A6: SYY 871829107 2868165 NYSE Common stock
A7: Source: FactSet Fundamentals
B8: DEC '25 | C8: JUN '25 | D8: JUN '24 | E8: JUN '23 | F8: JUN '22 | G8: JUN '21 | H8: JUN '20 | I8: JUN '19 | J8: JUN '18 | K8: JUN '17 | L8: JUN '16 | M8: JUN '15 | N8: JUN '14 | O8: JUN '13 | P8: JUN '12 | Q8: JUN '11 | R8: JUN '10 | S8: JUN '09 | T8: JUN '08 | U8: JUN '07 | V8: JUN '06 | W8: JUN '05 | X8: JUN '04 | Y8: JUN '03 | Z8: JUN '02 | AA8: JUN '01 | AB8: JUN '00 | AC8: JUN '99 | AD8: JUN '98 | AE8: JUN '97 | AF8: JUN '96
B9: LTM
J10: Restate | K10: Restate
A11: Sales | B11: 82646 | C11: 81370 | D11: 78844 | E11: 76324.675 | F11: 68636.146 | G11: 51297.843 | H11: 52893.31 | I11: 60113.922 | J11: 58727.324 | K11: 55371.139 | L11: 50366.919 | M11: 48680.752 | N11: 46516.712 | O11: 44411.233 | P11: 42380.939 | Q11: 39323.489 | R11: 37243.495 | S11: 36853.33 | T11: 37522.111 | U11: 35042.075 | V11: 32628.438 | W11: 30281.914 | X11: 29335.403 | Y11: 26140 | Z11: 23351 | AA11: 21785 | AB11: 19303.268 | AC11: 17422.815 | AD11: 15327.536 | AE11: 14454.589 | AF11: 13395.13
A12: Cost of Goods Sold (COGS) incl. D&A | B12: 67484 | C12: 67332 | D12: 65092 | E12: 62474.678 | F12: 56421.622 | G12: 42573.402 | H12: 43700.472 | I12: 49362.044 | J12: 48258.509 | K12: 45579.032 | L12: 41935.147 | M12: 40625.036 | N12: 38829.477 | O12: 37017.142 | P12: 35089.262 | Q12: 32376.341 | R12: 30497.709 | S12: 30178.061 | T12: 30679.823 | U12: 28284.603 | V12: 26337.107 | W12: 24498.2 | X12: 23661.514 | Y12: 20980.412 | Z12: 18722.251 | AA12: 17513 | AB12: 15649.551 | AC12: 14207.86 | AD12: 12499.636 | AE12: 11835.959 | AF12: 10983.796
A13: COGS excluding D&A | B13: 66394 | C13: 66246 | D13: 64098 | E13: 61585.505 | F13: 55539.97 | G13: 41720.996 | H13: 42791.596 | I13: 48613.144 | J13: 47529.009 | K13: 44700.732 | L13: 41289.147 | M13: 40089.236 | N13: 38293.477 | O13: 36511.542 | P13: 34679.462 | Q13: 31980.441 | R13: 30115.109 | S13: 29801.253 | T13: 30313.389 | U13: 27930.178 | V13: 26005.665 | W13: 24192.52 | X13: 23377.919 | Y13: 20707 | Z13: 18444 | AA13: 17265 | AB13: 15428.89 | AC13: 14002.855 | AD13: 12318.402 | AE13: 11675.667 | AF13: 10839.087
A14: Depreciation & Amortization Expense | B14: 1090 | C14: 1086 | D14: 994 | E14: 889.173 | F14: 881.652 | G14: 852.406 | H14: 908.876 | I14: 748.9 | J14: 729.5 | K14: 878.3 | L14: 646 | M14: 535.8 | N14: 536 | O14: 505.6 | P14: 409.8 | Q14: 395.9 | R14: 382.6 | S14: 376.808 | T14: 366.434 | U14: 354.425 | V14: 331.442 | W14: 305.68 | X14: 283.595 | Y14: 273.412 | Z14: 278.251 | AA14: 248 | AB14: 220.661 | AC14: 205.005 | AD14: 181.234 | AE14: 160.292 | AF14: 144.709
A15: Depreciation | C15: 939 | D15: 852 | E15: 762.873 | F15: 748.752 | G15: 748.906 | H15: 813.576 | I15: 656.6 | J15: 614.8 | K15: 765.4 | L15: 608.7 | M15: 495.8 | N15: 493.8 | O15: 473.5 | P15: 384.9 | Q15: 374 | R15: 361.7 | S15: 361.062 | T15: 352.569 | U15: 341.714 | V15: 320.669 | W15: 298.111 | X15: 273.03 | Y15: 263.48 | Z15: 243.498 | AA15: 236
A16: Amortization of Intangibles | C16: 147 | D16: 142 | E16: 126.3 | F16: 132.9 | G16: 103.5 | H16: 95.3 | I16: 92.3 | J16: 114.7 | K16: 112.9 | L16: 37.3 | M16: 40 | N16: 42.2 | O16: 32.1 | P16: 24.9 | Q16: 21.9 | R16: 20.9 | S16: 15.746 | T16: 13.865 | U16: 12.711 | V16: 10.773 | W16: 7.569 | X16: 10.565 | Y16: 9.932 | Z16: 34.753 | AA16: 12
A17: Gross Income | B17: 15162 | C17: 14038 | D17: 13752 | E17: 13849.997 | F17: 12214.524 | G17: 8724.441 | H17: 9192.838 | I17: 10751.878 | J17: 10468.815 | K17: 9792.107 | L17: 8431.772 | M17: 8055.716 | N17: 7687.235 | O17: 7394.091 | P17: 7291.677 | Q17: 6947.148 | R17: 6745.786 | S17: 6675.269 | T17: 6842.288 | U17: 6757.472 | V17: 6291.331 | W17: 5783.714 | X17: 5673.889 | Y17: 5159.588 | Z17: 4628.749 | AA17: 4272 | AB17: 3653.717 | AC17: 3214.955 | AD17: 2827.9 | AE17: 2618.63 | AF17: 2411.334
A18: SG&A Expense | B18: 11692 | C18: 10526 | D18: 10270 | E18: 10708.566 | F18: 9784.725 | G18: 7133.31 | H18: 7677.992 | I18: 8259.317 | J18: 8079.518 | K18: 7579.736 | L18: 6422.572 | M18: 6263.886 | N18: 5951.727 | O18: 5352.23 | P18: 5205.225 | Q18: 5015.646 | R18: 4769.918 | S18: 4803.058 | T18: 4962.339 | U18: 5048.99 | V18: 4796.301 | W18: 4194.184 | X18: 4141.23 | Y18: 3836 | Z18: 3468 | AA18: 3233 | AB18: 2843.755 | AD18: 2236.932 | AE18: 2076.335 | AF18: 1917.376
A19: Other SG&A | B19: 11692 | C19: 10526 | D19: 10270 | E19: 10708.566 | F19: 9784.725 | G19: 7133.31 | H19: 7677.992 | I19: 8259.317 | J19: 8079.518 | K19: 7579.736 | L19: 6422.572 | M19: 6263.886 | N19: 5951.727 | O19: 5352.23 | P19: 5205.225 | Q19: 5015.646 | R19: 4769.918 | S19: 4803.058 | T19: 4962.339 | U19: 5048.99 | V19: 4796.301 | W19: 4194.184 | X19: 4141.23 | Y19: 3836 | Z19: 3468 | AA19: 3233 | AB19: 2843.755 | AD19: 2236.932 | AE19: 2076.335 | AF19: 1917.376
A20: Other Operating Expense | B20: 0 | C20: 0 | D20: 0 | E20: 0 | F20: 0 | G20: 0 | H20: 0 | I20: 0 | J20: 0 | K20: 0 | L20: 0 | M20: 0 | N20: 0 | O20: 0 | P20: 0 | Q20: 0 | R20: 0 | S20: 0 | T20: 0 | U20: 0 | V20: 0 | W20: 0 | X20: 0 | Y20: -0.412 | Z20: -0.251 | AA20: 0 | AB20: 0 | AC20: 2547.266 | AD20: 0 | AE20: 0 | AF20: 0
A21: EBIT (Operating Income) | B21: 3470 | C21: 3512 | D21: 3482 | E21: 3141.431 | F21: 2429.799 | G21: 1591.131 | H21: 1514.846 | I21: 2492.561 | J21: 2389.297 | K21: 2212.371 | L21: 2009.2 | M21: 1791.83 | N21: 1735.508 | O21: 2041.861 | P21: 2086.452 | Q21: 1931.502 | R21: 1975.868 | S21: 1872.211 | T21: 1879.949 | U21: 1708.482 | V21: 1495.03 | W21: 1589.53 | X21: 1532.659 | Y21: 1324 | Z21: 1161 | AA21: 1039 | AB21: 809.962 | AC21: 667.689 | AD21: 590.968 | AE21: 542.295 | AF21: 493.958
A22: Nonoperating Income - Net | B22: -55 | C22: -33 | D22: -42 | E22: -267.023 | F22: 71.821 | G22: -4.29 | H22: -77.829 | I22: 33.306 | J22: 41.911 | K22: 4.442 | L22: -122.89 | M22: 25.287 | N22: 11.618 | O22: 17.472 | P22: 6.766 | Q22: 14.219 | R22: -0.802 | S22: 14.945 | T22: 22.93 | U22: 17.735 | V22: 9.016 | W22: 10.906 | X22: 12.365 | Y22: 8 | Z22: 3 | AA22: 0 | AB22: 11.478 | AC22: -0.963 | AD22: -0.053 | AE22: 0.162 | AF22: 1.004
A23: Other Income (Expense) | B23: -55 | C23: -33 | D23: -42 | E23: -267.023 | F23: 71.821 | G23: -4.29 | H23: -77.829 | I23: 33.306 | J23: 41.911 | K23: 4.442 | L23: -122.89 | M23: 25.287 | N23: 11.618 | O23: 17.472 | P23: 6.766 | Q23: 14.219 | R23: -0.802 | S23: 14.945 | T23: 22.93 | U23: 17.735 | V23: 9.016 | W23: 10.906 | X23: 12.365 | Y23: 8 | Z23: 3 | AA23: 0 | AB23: 11.478 | AC23: -0.963 | AD23: -0.053 | AE23: 0.162 | AF23: 1.004
A24: Interest Expense | B24: 583 | C24: 588 | D24: 578 | E24: 500.3 | F24: 470.264 | G24: 505.039 | H24: 339.958 | I24: 273.909 | J24: 314.026 | K24: 291.383 | L24: 220.176 | M24: 130.04 | N24: 133.995 | O24: 132.361 | P24: 120.604 | Q24: 127.293 | R24: 136.034 | S24: 116.322 | T24: 111.541 | U24: 105.002 | V24: 109.1 | W24: 75 | X24: 69.88 | Y24: 72 | Z24: 63 | AA24: 72 | AB24: 70.832 | AC24: 72.839 | AD24: 58.422 | AE24: 46.502 | AF24: 41.019
A25: Gross Interest Expense | B25: 583 | C25: 588 | D25: 578 | E25: 500.3 | F25: 470.264 | G25: 505.039 | H25: 339.958 | I25: 273.909 | J25: 314.026 | K25: 293.421 | L25: 222.208 | M25: 130.906 | N25: 135.092 | O25: 136.603 | P25: 141.404 | Q25: 141.193 | R25: 146.034 | S25: 119.853 | T25: 118.346 | U25: 108.957 | V25: 111.953 | W25: 79.316 | X25: 77.375 | Y25: 77 | Z25: 67 | AA25: 75 | AB25: 71.796 | AC25: 74.651 | AD25: 60.517 | AE25: 48.717 | AF25: 43.802
A26: Interest Capitalized | B26: 0 | C26: 0 | D26: 0 | E26: 0 | F26: 0 | G26: 0 | H26: 0 | I26: 0 | J26: 0 | K26: 2.038 | L26: 2.032 | M26: 0.866 | N26: 1.097 | O26: 4.242 | P26: 20.8 | Q26: 13.9 | R26: 10 | S26: 3.531 | T26: 6.805 | U26: 3.955 | V26: 2.853 | W26: 4.316 | X26: 7.495 | Y26: 5 | Z26: 4 | AA26: 3 | AB26: 0.964 | AC26: 1.812 | AD26: 2.095 | AE26: 2.215 | AF26: 2.783
A27: Unusual Expense - Net | B27: 482 | C27: 476 | D27: 297 | E27: 88.753 | F27: 284.583 | G27: 497.074 | H27: 803.675 | I27: 246.122 | J27: 160.958 | K27: 159.2 | L27: 233.127 | M27: 678.93 | N27: 137.507 | O27: 379.517 | P27: 188.612 | Q27: -9.026 | R27: -10.557 | S27: 0 | T27: 0 | U27: 0 | V27: 0 | W27: 0 | X27: 0 | Y27: 0 | Z27: 0 | AA27: 0 | AB27: 0
A28: Impairments | C28: 92 | G28: 0 | H28: 203.206
A29: Goodwill | B29: 92 | C29: 92 | D29: 0 | E29: 0 | F29: 0 | G29: 0 | H29: 203.206 | I29: 0 | J29: 0 | K29: 0 | L29: 0 | M29: 0 | N29: 0 | O29: 0 | P29: 0 | Q29: 0 | R29: 0 | S29: 0 | T29: 0 | U29: 0 | V29: 0 | W29: 0 | X29: 0 | Y29: 0 | Z29: 0 | AA29: 0 | AB29: 0
A30: Exceptional Provisions | H30: 323.403 | L30: 0 | M30: 0 | N30: 20 | S30: 0 | T30: 0 | U30: 0 | V30: 0 | W30: 0
A31: Restructuring Expense | B31: 321 | C31: 343 | D31: 279 | E31: 73.854 | F31: 142.705 | G31: 133.727 | H31: 220.3 | I31: 171.1 | J31: 91 | K31: 159.2 | L31: 158.7 | M31: 700.89 | N31: 104.545 | O31: 383.383 | P31: 199.541 | Q31: 0 | R31: 0 | S31: 0 | T31: 0 | U31: 0 | V31: 0 | W31: 0 | X31: 0 | Y31: 0 | Z31: 0 | AA31: 0 | AB31: 0 | AC31: 0 | AD31: 0 | AE31: 0 | AF31: 0
A32: Unrealized Valuation Gain/Loss | B32: -69 | C32: -41 | D32: -18 | E32: -14.899 | F32: -26.275 | G32: -69.45 | H32: -56.766 | I32: -75.022 | J32: -69.958 | K32: 0 | L32: 12.033 | M32: 21.96 | N32: 10.879 | O32: 3.866 | P32: 7.208 | Q32: 9.026 | R32: 10.557
A33: Hedges/Derivatives | B33: -69 | C33: -41 | D33: -18 | E33: -14.899 | F33: -26.275 | G33: -69.45 | H33: -56.766 | I33: -75.022 | J33: -69.958 | K33: 0 | L33: 12.033 | M33: 21.96 | N33: 10.879 | O33: 3.866 | P33: 7.208 | Q33: 9.026 | R33: 10.557
A34: Excpl Chrgs - Others | E34: 0 | F34: 115.603 | G34: 293.897 | L34: 86.46 | M34: 0 | N34: 23.841 | P34: -3.721
A35: Restructuring of Debt | E35: 0 | F35: 115.603 | G35: 293.897 | L35: 86.46
A36: Calamitous Events | M36: 0 | N36: 23.841 | P36: -3.721
A37: Pretax Income | B37: 2350 | C37: 2415 | D37: 2565 | E37: 2285.355 | F37: 1746.773 | G37: 584.728 | H37: 293.384 | I37: 2005.836 | J37: 1956.224 | K37: 1766.23 | L37: 1433.007 | M37: 1008.147 | N37: 1475.624 | O37: 1547.455 | P37: 1784.002 | Q37: 1827.454 | R37: 1849.589 | S37: 1770.834 | T37: 1791.338 | U37: 1621.215 | V37: 1394.946 | W37: 1525.436 | X37: 1475.144 | Y37: 1260 | Z37: 1101 | AA37: 967 | AB37: 737.608 | AC37: 593.887 | AD37: 532.493 | AE37: 495.955 | AF37: 453.943
A38: Income Taxes | B38: 553 | C38: 587 | D38: 610 | E38: 515.231 | F38: 388.005 | G38: 60.519 | H38: 77.909 | I38: 331.565 | J38: 525.458 | K38: 623.727 | L38: 483.385 | M38: 321.374 | N38: 544.091 | O38: 555.028 | P38: 662.417 | Q38: 675.424 | R38: 669.606 | S38: 714.886 | T38: 685.187 | U38: 620.139 | V38: 548.906 | W38: 563.979 | X38: 567.93 | Y38: 482 | Z38: 421 | AA38: 370 | AB38: 283.979 | AC38: 231.616 | AD38: 207.672 | AE38: 193.422 | AF38: 177.038
A39: Income Taxes - Current Domestic | C39: 602 | D39: 584 | E39: 531.665 | F39: 452.459 | G39: 218.383 | H39: 269.226 | I39: 458.284 | J39: 337.55 | K39: 675.573 | L39: 385.183 | M39: 327.639 | N39: 574.76 | O39: 582.889 | P39: 840.745 | Q39: 840.173 | R39: 791.12 | S39: 1010.595 | T39: 664.171 | U39: 539.997 | V39: 486.642 | W39: 485.499 | X39: 94.173 | Y39: 1 | Z39: 158 | AA39: 364 | AB39: 283.979 | AC39: 231.616 | AD39: 207.672 | AE39: 193.422 | AF39: 177.038
A40: Income Taxes - Current Foreign | C40: 0 | D40: 0 | E40: 0 | F40: 0 | G40: 0 | H40: 0 | I40: 0 | J40: 0 | K40: 0 | L40: 0 | M40: 0 | N40: 0 | O40: 0 | P40: 0 | Q40: 0 | R40: 0 | S40: 0 | T40: 21.016 | U40: 80.142 | V40: 62.264 | W40: 78.48 | X40: 0 | Y40: 0 | Z40: 0 | AA40: 0 | AB40: 0 | AC40: 0 | AD40: 0 | AE40: 0 | AF40: 0
A41: Income Taxes - Deferred Domestic | C41: -15 | D41: 26 | E41: -16.434 | F41: -64.454 | G41: -157.864 | H41: -191.317 | I41: -126.719 | J41: 187.908 | K41: -51.846 | L41: 98.202 | M41: -6.265 | N41: -30.669 | O41: -27.861 | P41: -178.328 | Q41: -164.749 | R41: -121.514 | S41: -295.709 | T41: 0 | U41: 0 | V41: 0 | W41: 0 | X41: 473.757 | Y41: 481 | Z41: 263 | AA41: 6
A42: Consolidated Net Income | B42: 1797 | C42: 1828 | D42: 1955 | E42: 1770.124 | F42: 1358.768 | G42: 524.209 | H42: 215.475 | I42: 1674.271 | J42: 1430.766 | K42: 1142.503 | L42: 949.622 | M42: 686.773 | N42: 931.533 | O42: 992.427 | P42: 1121.585 | Q42: 1152.03 | R42: 1179.983 | S42: 1055.948 | T42: 1106.151 | U42: 1001.076 | V42: 846.04 | W42: 961.457 | X42: 907.214 | Y42: 778 | Z42: 680 | AA42: 597 | AB42: 453.629 | AC42: 362.271 | AD42: 324.821 | AE42: 302.533 | AF42: 276.905
...

Sheet Balance Sheet
A1: Sysco Corporation (SYY)
A2: $71.53
A5: Sysco Corporation
A6: SYY 871829107 2868165 NYSE Common stock
A7: Source: FactSet Fundamentals
B8: JUN '25 | C8: JUN '24 | D8: JUN '23 | E8: JUN '22 | F8: JUN '21 | G8: JUN '20 | H8: JUN '19 | I8: JUN '18 | J8: JUN '17 | K8: JUN '16 | L8: JUN '15 | M8: JUN '14 | N8: JUN '13 | O8: JUN '12 | P8: JUN '11 | Q8: JUN '10 | R8: JUN '09 | S8: JUN '08 | T8: JUN '07 | U8: JUN '06 | V8: JUN '05 | W8: JUN '04 | X8: JUN '03 | Y8: JUN '02 | Z8: JUN '01 | AA8: JUN '00 | AB8: JUN '99 | AC8: JUN '98 | AD8: JUN '97 | AE8: JUN '96
I9: Restate | J9: Restate
A10: Assets
A11: Cash & Short-Term Investments | B11: 1071 | C11: 696 | D11: 745.201 | E11: 867.086 | F11: 3007.123 | G11: 6059.427 | H11: 513.46 | I11: 552.325 | J11: 869.502 | K11: 3919.3 | L11: 5130.044 | M11: 413.046 | N11: 412.285 | O11: 688.867 | P11: 639.765 | Q11: 608.954 | R11: 1087.084 | S11: 551.552 | T11: 207.872 | U11: 201.897 | V11: 191.678 | W11: 199.706 | X11: 337.447 | Y11: 230.439 | Z11: 135.743 | AA11: 159.128 | AB11: 149.303 | AC11: 110.288 | AD11: 117.696 | AE11: 107.759
A12: Cash Only | B12: 1071 | C12: 696 | D12: 745.201 | E12: 867.086 | F12: 3007.123 | G12: 6059.427 | H12: 513.46 | I12: 552.325 | J12: 869.502 | K12: 3919.3 | L12: 5130.044 | M12: 413.046 | N12: 412.285 | O12: 688.867 | P12: 639.765 | Q12: 585.443 | R12: 1087.084 | S12: 551.552 | T12: 207.872 | U12: 201.897 | V12: 191.678 | W12: 199.706 | X12: 337.447 | Y12: 230.439 | Z12: 135.743 | AA12: 159.128 | AB12: 149.303 | AC12: 110.288 | AD12: 117.696 | AE12: 107.759
A13: Total Short Term Investments | B13: 0 | C13: 0 | D13: 0 | E13: 0 | F13: 0 | G13: 0 | H13: 0 | I13: 0 | J13: 0 | K13: 0 | L13: 0 | M13: 0 | N13: 0 | O13: 0 | P13: 0 | Q13: 23.511 | R13: 0 | S13: 0 | T13: 0 | U13: 0 | V13: 0 | W13: 0 | X13: 0 | Y13: 0 | Z13: 0 | AA13: 0 | AB13: 0 | AC13: 0 | AD13: 0 | AE13: 0
A14: Short-Term Receivables | B14: 5506 | C14: 5346 | D14: 5097.785 | E14: 4874.846 | F14: 3790.269 | G14: 3001.557 | H14: 4201.429 | I14: 4137.835 | J14: 4029.153 | K14: 3380.971 | L14: 3353.381 | M14: 3398.713 | N14: 3183.114 | O14: 2966.624 | P14: 2898.283 | Q14: 2617.352 | R14: 2468.511 | S14: 2723.189 | T14: 2610.885 | U14: 2483.72 | V14: 2284.033 | W14: 2189.127 | X14: 2009.627 | Y14: 1760.827 | Z14: 1658.044 | AA14: 1519.038 | AB14: 1334.371 | AC14: 1215.61 | AD14: 1065.002 | AE14: 1039.759
A15: Accounts Receivables, Net | B15: 5502 | C15: 5324 | D15: 5091.97 | E15: 4838.912 | F15: 3781.51 | G15: 2893.551 | H15: 4181.696 | I15: 4073.723 | J15: 4012.393 | K15: 3380.971 | L15: 3353.381 | M15: 3398.713 | N15: 3183.114 | O15: 2966.624 | P15: 2898.283 | Q15: 2617.352 | R15: 2468.511 | S15: 2723.189 | T15: 2610.885 | U15: 2483.72 | V15: 2284.033 | W15: 2189.127 | X15: 2009.627 | Y15: 1760.827 | Z15: 1658.044 | AA15: 1519.038 | AC15: 1215.61 | AD15: 1065.002 | AE15: 1039.759
A16: Accounts Receivables, Gross | B16: 5519 | C16: 5378 | D16: 5137.569 | E16: 4909.702 | F16: 3899.205 | G16: 3228.361 | H16: 4209.872 | I16: 4099.491 | J16: 4043.452 | K16: 3418.851 | L16: 3395.101 | M16: 3448.615 | N16: 3230.459 | O16: 3009.543 | P16: 2940.719 | Q16: 2653.925 | R16: 2504.589 | S16: 2754.919 | T16: 2642.726 | U16: 2512.82 | V16: 2313.637 | W16: 2223.302 | X16: 2044.632 | Y16: 1791.165 | Z16: 1686.028 | AA16: 1546.666 | AB16: 21.095 | AC16: 1235.691 | AD16: 1082.242 | AE16: 1056.139
A17: Bad Debt/Doubtful Accounts | B17: -17 | C17: -54 | D17: -45.599 | E17: -70.79 | F17: -117.695 | G17: -334.81 | H17: -28.176 | I17: -25.768 | J17: -31.059 | K17: -37.88 | L17: -41.72 | M17: -49.902 | N17: -47.345 | O17: -42.919 | P17: -42.436 | Q17: -36.573 | R17: -36.078 | S17: -31.73 | T17: -31.841 | U17: -29.1 | V17: -29.604 | W17: -34.175 | X17: -35.005 | Y17: -30.338 | Z17: -27.984 | AA17: -27.628 | AB17: -21.095 | AC17: -20.081 | AD17: -17.24 | AE17: -16.38
A18: Other Receivables | B18: 4 | C18: 22 | D18: 5.815 | E18: 35.934 | F18: 8.759 | G18: 108.006 | H18: 19.733 | I18: 64.112 | J18: 16.76 | K18: 0 | L18: 0 | M18: 0 | N18: 0 | O18: 0 | P18: 0 | Q18: 0 | R18: 0 | S18: 0 | T18: 0 | U18: 0 | V18: 0 | W18: 0 | X18: 0 | Y18: 0 | Z18: 0 | AA18: 0 | AC18: 0 | AD18: 0 | AE18: 0
A19: Inventories | B19: 5053 | C19: 4678 | D19: 4480.812 | E19: 4437.498 | F19: 3695.219 | G19: 3095.085 | H19: 3216.034 | I19: 3125.413 | J19: 2995.598 | K19: 2639.174 | L19: 2691.823 | M19: 2602.018 | N19: 2396.188 | O19: 2178.83 | P19: 2073.766 | Q19: 1771.539 | R19: 1650.666 | S19: 1836.478 | T19: 1714.187 | U19: 1608.233 | V19: 1466.161 | W19: 1404.41 | X19: 1230.08 | Y19: 1117.869 | Z19: 1061.893 | AA19: 937.899 | AB19: 851.965 | AC19: 790.501 | AD19: 733.782 | AE19: 723.937
A20: Finished Goods | B20: 5053 | C20: 4678 | D20: 4480.812 | E20: 4437.498 | F20: 3695.219 | G20: 3095.085 | H20: 3216.034 | I20: 3125.413 | J20: 2995.598 | K20: 2639.174 | L20: 2691.823 | M20: 2602.018 | N20: 2396.188 | O20: 2178.83 | P20: 2073.766 | Q20: 1771.539 | R20: 1650.666 | S20: 1836.478 | T20: 1714.187 | U20: 1608.233 | V20: 1466.161 | W20: 1404.41 | X20: 1230.08 | Y20: 1117.869 | Z20: 1061.893 | AA20: 937.899 | AB20: 851.965
A21: Other Current Assets | B21: 338 | C21: 323 | D21: 284.566 | E21: 303.789 | F21: 240.956 | G21: 192.163 | H21: 210.582 | I21: 187.88 | J21: 139.185 | K21: 114.454 | L21: 319.056 | M21: 268.195 | N21: 215.84 | O21: 250.487 | P21: 121.068 | Q21: 78.413 | R21: 64.418 | S21: 63.814 | T21: 142.602 | U21: 105.844 | V21: 59.914 | W21: 58.168 | X21: 52.38 | Y21: 76.154 | Z21: 129.202 | AA21: 117.15 | AB21: 73.128 | AC21: 63.668 | AD21: 47.937 | AE21: 50.872
