Workbook

Sheet Summary
B1: Netflix, Inc.
B3: Enterprise Value ($ billions)
B4: December 31, 2023 | D4: Market | F4: 219
D5: Model | F5: =DCF!J24/1000 -> 253.29994
D6: Diff [%] | F6: =F5/F4 -1 -> 0.15662074
D7: Discount Rate
C8: =DCF!B30/1000 -> 253299.94 | D8: 0.08 | E8: 0.08 | F8: 0.09 | G8: 0.095 | H8: 0.1
B9: growth rate | C9: 0.02 | D9: 310763.05 | E9: 310763.05 | F9: 262312.92 | G9: 242985.25 | H9: 226105.23
C10: 0.025 | D10: 335594.62 | E10: 335594.62 | F10: 279670.76 | G10: 257755.82 | H10: 238796.1
C11: 0.0275 | D11: 349784.09 | E11: 349784.09 | F11: 289391.16 | G11: 265961.7 | H11: 245797.95
C12: 0.03 | D12: 365392.51 | E12: 365392.51 | F12: 299921.58 | G12: 274798.8 | H12: 253299.94
C13: 0.035 | D13: 401812.15 | E13: 401812.15 | F13: 323854.37 | G13: 294682.26 | H13: 270035.15
A16: Financial Summary
C17: Income Statement [$millions] | J17: Balance Sheets [$millions] | U17: Ratio and Growth Analysis
D18: Year ended December 31, | M18: As of December 31, | U18: Year ended December 31,
D19: 2024 | E19: 2025 | F19: 2026 | G19: 2027 | H19: 2028 | M19: 2023 | N19: 2024 | O19: 2025 | P19: 2026 | Q19: 2027 | R19: 2028 | V19: 2024 | W19: 2025 | X19: 2026 | Y19: 2027 | Z19: 2028
C20: Revenue | D20: =IS!E4/1000 -> 38107.326 | E20: =IS!F4/1000 -> 43061.278 | F20: =IS!G4/1000 -> 48874.55 | G20: =IS!H4/1000 -> 55472.615 | H20: =IS!I4/1000 -> 63238.781 | J20: =BS!A4 -> Cash and cash equivalents | M20: =BS!E4/1000 -> 7116.913 | N20: =BS!F4/1000 -> 11468.484 | O20: =BS!G4/1000 -> 18804.032 | P20: =BS!H4/1000 -> 29654.191 | Q20: =BS!I4/1000 -> 44805.316 | R20: =BS!J4/1000 -> 64823.762 | T20: Current Ratio | V20: =BS!F7/BS!F18 -> 1.4689069 | W20: =BS!G7/BS!G18 -> 1.9971612 | X20: =BS!H7/BS!H18 -> 2.6618767 | Y20: =BS!I7/BS!I18 -> 3.4503385 | Z20: =BS!J7/BS!J18 -> 4.3071014
J21: Total Assets | M21: =BS!E11/1000 -> 48731.992 | N21: =BS!F11/1000 -> 56022.675 | O21: =BS!G11/1000 -> 65268.061 | P21: =BS!H11/1000 -> 76972.416 | Q21: =BS!I11/1000 -> 91619.249 | R21: =BS!J11/1000 -> 109729.83
C22: Operating Income | D22: =IS!E9/1000 -> 8241.7779 | E22: =IS!F9/1000 -> 10060.86 | F22: =IS!G9/1000 -> 12250.875 | G22: =IS!H9/1000 -> 14835.078 | H22: =IS!I9/1000 -> 17893.956 | T22: Operating Margin | V22: =IS!E9/IS!E4 -> 0.21627805 | W22: =IS!F9/IS!F4 -> 0.23364054 | X22: =IS!G9/IS!G4 -> 0.25065959 | Y22: =IS!H9/IS!H4 -> 0.26743066 | Z22: =IS!I9/IS!I4 -> 0.28295859
C23: Net Income | D23: =IS!E15/1000 -> 6858.7766 | E23: =IS!F15/1000 -> 8574.9355 | F23: =IS!G15/1000 -> 10678.432 | G23: =IS!H15/1000 -> 13295.272 | H23: =IS!I15/1000 -> 16278.564 | T23: Profit Margin | V23: =IS!E15/IS!E4 -> 0.17998578 | W23: =IS!F15/IS!F4 -> 0.19913333 | X23: =IS!G15/IS!G4 -> 0.21848656 | Y23: =IS!H15/IS!H4 -> 0.2396727 | Z23: =IS!I15/IS!I4 -> 0.25741426
J24: Content Assets | M24: =BS!E8/1000 -> 31658.056 | N24: =BS!F8/1000 -> 33466.798 | O24: =BS!G8/1000 -> 34060.24 | P24: =BS!H8/1000 -> 33341.157 | Q24: =BS!I8/1000 -> 31027.357 | R24: =BS!J8/1000 -> 26975.315 | T24: EBITDA margin | V24: =Summary!D25/Summary!D20 -> 0.64286921 | W24: =Summary!E25/Summary!E20 -> 0.64348373 | X24: =Summary!F25/Summary!F20 -> 0.64399869 | Y24: =Summary!G25/Summary!G20 -> 0.65123475 | Z24: =Summary!H25/Summary!H20 -> 0.65390732
C25: Adjusted EBITDA | D25: =(IS!E15-IS!E11-IS!E14+IS!E18+IS!E20+IS!E19)/1000 -> 24498.026 | E25: =(IS!F15-IS!F11-IS!F14+IS!F18+IS!F20+IS!F19)/1000 -> 27709.232 | F25: =(IS!G15-IS!G11-IS!G14+IS!G18+IS!G20+IS!G19)/1000 -> 31475.146 | G25: =(IS!H15-IS!H11-IS!H14+IS!H18+IS!H20+IS!H19)/1000 -> 36125.694 | H25: =(IS!I15-IS!I11-IS!I14+IS!I18+IS!I20+IS!I19)/1000 -> 41352.302 | J25: Current Content Liabilities | M25: =BS!E13/1000 -> 4466.47 | N25: =BS!F13/1000 -> 5047.1111 | O25: =BS!G13/1000 -> 5703.2355 | P25: =BS!H13/1000 -> 6473.1723 | Q25: =BS!I13/1000 -> 7347.0506 | R25: =BS!J13/1000 -> 8375.6377
J26: Long-term debt | M26: =BS!E20/1000 -> 14143.417 | N26: =BS!F20/1000 -> 14139.417 | O26: =BS!G20/1000 -> 14135.417 | P26: =BS!H20/1000 -> 14131.417 | Q26: =BS!I20/1000 -> 14127.417 | R26: =BS!J20/1000 -> 14123.417 | T26: ROE | V26: =D23/AVERAGE(M32:N32) -> 0.29371729 | W26: =E23/AVERAGE(N32:O32) -> 0.28832342 | X26: =F23/AVERAGE(O32:P32) -> 0.28065411 | Y26: =G23/AVERAGE(P32:Q32) -> 0.27286202 | Z26: =H23/AVERAGE(Q32:R32) -> 0.26166506
C27: Cash Flows [$millions] | J27: Total Liabilitiies | M27: =BS!E22/1000 -> 28143.679 | N27: =BS!F22/1000 -> 29907.733 | O27: =BS!G22/1000 -> 31901.635 | P27: =BS!H22/1000 -> 34242.095 | Q27: =BS!I22/1000 -> 36899.058 | R27: =BS!J22/1000 -> 40027.109 | T27: ROA | V27: =D23/AVERAGE(M21:N21) -> 0.13094933 | W27: =E23/AVERAGE(N21:O21) -> 0.14139473 | X27: =F23/AVERAGE(O21:P21) -> 0.15014618 | Y27: =G23/AVERAGE(P21:Q21) -> 0.15772158 | Z27: =H23/AVERAGE(Q21:R21) -> 0.16169495
D28: Year ended December 31,
D29: 2024 | E29: 2025 | F29: 2026 | G29: 2027 | H29: 2028 | J29: Net Working Capital | M29: =(BS!E7-BS!E18)/1000 -> 1057.478 | N29: =(BS!F7-BS!F18)/1000 -> 4670.5758 | O29: =(BS!G7-BS!G18)/1000 -> 11171.649 | P29: =(BS!H7-BS!H18)/1000 -> 21042.584 | Q29: =(BS!I7-BS!I18)/1000 -> 35082.289 | R29: =(BS!J7-BS!J18)/1000 -> 53792.554 | T29: Revenue Growth | V29: =IS!E4/IS!D4 -1 -> 0.13 | W29: =IS!F4/IS!E4 -1 -> 0.13 | X29: =IS!G4/IS!F4 -1 -> 0.135 | Y29: =IS!H4/IS!G4 -1 -> 0.135 | Z29: =IS!I4/IS!H4 -1 -> 0.14
C30: Operatig Cash Flows | D30: ='SCF forecast'!B17/1000 -> 6429.4348 | E30: ='SCF forecast'!C17/1000 -> 9464.614 | F30: ='SCF forecast'!D17/1000 -> 13039.309 | G30: ='SCF forecast'!E17/1000 -> 17408.47 | H30: ='SCF forecast'!F17/1000 -> 22356.06 | T30: FCFF Growth | W30: =E37/D37 -1 -> 0.45000558 | X30: =F37/E37 -1 -> 0.36553896 | Y30: =G37/F37 -1 -> 0.32758344 | Z30: =H37/G37 -1 -> 0.27924544
C32: Cash paid for Content Assets | D32: ='SCF forecast'!B16/1000 -> -17000 | E32: ='SCF forecast'!C16/1000 -> -17000 | F32: ='SCF forecast'!D16/1000 -> -17000 | G32: ='SCF forecast'!E16/1000 -> -17000 | H32: ='SCF forecast'!F16/1000 -> -17000 | J32: Total Equity | M32: =BS!E28/1000 -> 20588.313 | N32: =BS!F28/1000 -> 26114.942 | O32: =BS!G28/1000 -> 33366.426 | P32: =BS!H28/1000 -> 42730.32 | Q32: =BS!I28/1000 -> 54720.191 | R32: =BS!J28/1000 -> 69702.719
C33: CAPEX | D33: ='SCF forecast'!B18/1000 -> -393.86376 | E33: ='SCF forecast'!C18/1000 -> -445.06605 | F33: ='SCF forecast'!D18/1000 -> -505.14997 | G33: ='SCF forecast'!E18/1000 -> -573.34521 | H33: ='SCF forecast'!F18/1000 -> -653.61354
C34: Share Repurcahses | D34: ='SCF forecast'!B23/1000 -> -1680 | E34: ='SCF forecast'!C23/1000 -> -1680 | F34: ='SCF forecast'!D23/1000 -> -1680 | G34: ='SCF forecast'!E23/1000 -> -1680 | H34: ='SCF forecast'!F23/1000 -> -1680
C36: Free Cash flow [basic] | D36: =Summary!D30+Summary!D33 -> 6035.5711 | E36: =Summary!E30+Summary!E33 -> 9019.548 | F36: =Summary!F30+Summary!F33 -> 12534.159 | G36: =Summary!G30+Summary!G33 -> 16835.125 | H36: =Summary!H30+Summary!H33 -> 21702.446
C37: Enterprise Free Cash Flow | D37: =DCF!C14/1000 -> 6630.6138 | E37: =DCF!D14/1000 -> 9614.427 | F37: =DCF!E14/1000 -> 13128.875 | G37: =DCF!F14/1000 -> 17429.677 | H37: =DCF!G14/1000 -> 22296.834

Sheet IS
A1: CONSOLIDATED STATEMENTS OF OPERATIONS - USD ($) shares in Thousands, $ in Thousands | B1: 12 Months Ended December 31,
B2: 2021 | C2: 2022 | D2: 2023 | E2: 2024 | F2: 2025 | G2: 2026 | H2: 2027 | I2: 2028
A4: Revenues | B4: 29697844 | C4: 31615550 | D4: 33723297 | E4: =D4*(1+E23) -> 38107326 | F4: =E4*(1+F23) -> 43061278 | G4: =F4*(1+G23) -> 48874550 | H4: =G4*(1+H23) -> 55472615 | I4: =H4*(1+I23) -> 63238781
A5: Cost of revenues | B5: 17332683 | C5: 19168285 | D5: 19715368 | E5: =E4*E25 -> 22541105 | F5: =F4*F25 -> 25471448 | G5: =G4*G25 -> 28910094 | H5: =H4*H25 -> 32812957 | I5: =I4*I25 -> 37406770
A6: Marketing | B6: 2545146 | C6: 2530502 | D6: 2657883 | E6: =D6*(1+E26) -> 2790777.1 | F6: =E6*(1+F26) -> 2902408.2 | G6: =F6*(1+G26) -> 2989480.5 | H6: =G6*(1+H26) -> 3049270.1 | I6: =H6*(1+I26) -> 3110255.5
A7: Technology and development | B7: 2273885 | C7: 2711041 | D7: 2675758 | E7: =D7*(1+E27) -> 2675758 | F7: =E7*(1+F27) -> 2675758 | G7: =F7*(1+G27) -> 2675758 | H7: =G7*(1+H27) -> 2675758 | I7: =H7*(1+I27) -> 2675758
A8: General and administrative | B8: 1351621 | C8: 1572891 | D8: 1720285 | E8: =D8*(1+E28) -> 1857907.8 | F8: =E8*(1+F28) -> 1950803.2 | G8: =F8*(1+G28) -> 2048343.3 | H8: =G8*(1+H28) -> 2099551.9 | I8: =H8*(1+I28) -> 2152040.7
A9: Operating income | B9: 6194509 | C9: 5632831 | D9: 6954003 | E9: =E4-SUM(E5:E8) -> 8241777.9 | F9: =F4-SUM(F5:F8) -> 10060860 | G9: =G4-SUM(G5:G8) -> 12250875 | H9: =H4-SUM(H5:H8) -> 14835078 | I9: =I4-SUM(I5:I8) -> 17893956
A10: Other income (expense):
A11: Interest expense | B11: -765620 | C11: -706212 | D11: -699826 | E11: =-E31*(BS!E17+BS!E20) -> -686353.25 | F11: =-F31*(BS!F17+BS!F20) -> -686164.48 | G11: =-G31*(BS!G17+BS!G20) -> -685975.7 | H11: =-H31*(BS!H17+BS!H20) -> -685786.92 | I11: =-I31*(BS!I17+BS!I20) -> -685598.15
A12: Interest and other income (expense) | B12: 411214 | C12: 337310 | D12: -48772 | E12: =E30*BS!E4 -> 355845.65 | F12: =F30*BS!F4 -> 516081.78 | G12: =G30*BS!G4 -> 752161.28 | H12: =H30*BS!H4 -> 1186167.7 | I12: =I30*BS!I4 -> 1568186.1
A13: Income before income taxes | B13: 5840103 | C13: 5263929 | D13: 6205405 | E13: =SUM(E9:E12) -> 7911270.3 | F13: =SUM(F9:F12) -> 9890777.5 | G13: =SUM(G9:G12) -> 12317060 | H13: =SUM(H9:H12) -> 15335459 | I13: =SUM(I9:I12) -> 18776544
A14: Provision for income taxes | B14: -723875 | C14: -772005 | D14: -797415 | E14: =-E33*E13 -> -1052493.7 | F14: =-F33*F13 -> -1315841.9 | G14: =-G33*G13 -> -1638627.9 | H14: =-H33*H13 -> -2040187.4 | I14: =-I33*I13 -> -2497979.9
A15: Net income | B15: 5116228 | C15: 4491924 | D15: 5407990 | E15: =E13+E14 -> 6858776.6 | F15: =F13+F14 -> 8574935.5 | G15: =G13+G14 -> 10678432 | H15: =H13+H14 -> 13295272 | I15: =I13+I14 -> 16278564
A17: Significant non-cash items included in Operating Income (2021-2023 data from Cash Flow Statement)
A18: Depreciation and amortization of PP&E and intangibles | B18: 208412 | C18: 336682 | D18: 356947 | E18: =E35*BS!E9 -> 361292.9 | F18: =F35*BS!F9 -> 369182.98 | G18: =G35*BS!G9 -> 387565.18 | H18: =H35*BS!H9 -> 416049.35 | I18: =I35*BS!I9 -> 454153.28
A19: Stock-based compensation expense | B19: 403220 | C19: 575452 | D19: 339368 | E19: =D19*(1+E36) -> 347852.2 | F19: =E19*(1+F36) -> 356548.5 | G19: =F19*(1+G36) -> 365462.22 | H19: =G19*(1+H36) -> 374598.77 | I19: =H19*(1+I36) -> 383963.74
A20: Amortization of content assets | B20: 12230367 | C20: 14026132 | D20: 14197437 | E20: =D20*(1+E37) -> 15191258 | F20: =E20*(1+F37) -> 16406558 | G20: =F20*(1+G37) -> 17719083 | H20: =G20*(1+H37) -> 19313800 | I20: =H20*(1+I37) -> 21052042
A22: Modeling Assumptions | J22: Comments
A23: Revenue growth rate | C23: =+C4/B4-1 -> 0.064573913 | D23: =+D4/C4-1 -> 0.066668048 | E23: 0.13 | F23: 0.13 | G23: 0.135 | H23: 0.135 | I23: 0.14 | J23: Management guidance of 13-15% | M23: 0.13 | N23: 0.135 | O23: 0.14 | P23: 0.145 | Q23: 0.15
A25: COGS/revenue | B25: =+B5/B4 -> 0.58363439 | C25: =+C5/C4 -> 0.60629295 | D25: =+D5/D4 -> 0.5846216 | E25: =SUM($B$25:$D$25)/3 -> 0.59151631 | F25: =SUM($B$25:$D$25)/3 -> 0.59151631 | G25: =SUM($B$25:$D$25)/3 -> 0.59151631 | H25: =SUM($B$25:$D$25)/3 -> 0.59151631 | I25: =SUM($B$25:$D$25)/3 -> 0.59151631 | J25: Assume average historical data
A26: Marketing growth | C26: =+C6/B6-1 -> -0.0057536974 | D26: =+D6/C6-1 -> 0.050338233 | E26: 0.05 | F26: 0.04 | G26: 0.03 | H26: 0.02 | I26: 0.02 | J26: Fade over time
A27: T&D growth | C27: =+C7/B7-1 -> 0.19225071 | D27: =+D7/C7-1 -> -0.013014558 | E27: 0 | F27: 0 | G27: 0 | H27: 0 | I27: 0 | J27: No growth
A28: G&A growth | C28: =+C8/B8-1 -> 0.16370713 | D28: =+D8/C8-1 -> 0.093708973 | E28: 0.08 | F28: 0.05 | G28: 0.05 | H28: 0.025 | I28: 0.025 | J28: Fade over time
A30: interest income: return on cash | B30: =+B12/BS!B4 -> 0.05011413 | C30: =+C12/BS!C4 -> 0.055959019 | D30: =+D12/BS!D4 -> -0.0094754871 | E30: 0.05 | F30: 0.045 | G30: 0.04 | H30: 0.04 | I30: 0.035 | J30: Market Rates
A31: interest expense: implied rate on debt | B31: =+-B11/SUM(BS!B17,BS!B20) -> 0.04694471 | C31: =+-C11/SUM(BS!C17,BS!C20) -> 0.045879089 | D31: =+-D11/SUM(BS!D17,BS!D20) -> 0.048757911 | E31: =SUM($B$31:$D$31)/3 -> 0.047193903 | F31: =SUM($B$31:$D$31)/3 -> 0.047193903 | G31: =SUM($B$31:$D$31)/3 -> 0.047193903 | H31: =SUM($B$31:$D$31)/3 -> 0.047193903 | I31: =SUM($B$31:$D$31)/3 -> 0.047193903 | J31: Historical average
A33: ETR | B33: =+-B14/B13 -> 0.12394901 | C33: =+-C14/C13 -> 0.14665946 | D33: =+-D14/D13 -> 0.1285033 | E33: =SUM($B$33:$D$33)/3 -> 0.13303726 | F33: =SUM($B$33:$D$33)/3 -> 0.13303726 | G33: =SUM($B$33:$D$33)/3 -> 0.13303726 | H33: =SUM($B$33:$D$33)/3 -> 0.13303726 | I33: =SUM($B$33:$D$33)/3 -> 0.13303726 | J33: historical average
A35: D&A/PP&E (BoY) | B35: =B18/BS!B9 -> 0.21705446 | C35: =C18/BS!C9 -> 0.25439664 | D35: =D18/BS!D9 -> 0.25527997 | E35: =SUM($B$35:$D$35)/3 -> 0.24224369 | F35: =SUM($B$35:$D$35)/3 -> 0.24224369 | G35: =SUM($B$35:$D$35)/3 -> 0.24224369 | H35: =SUM($B$35:$D$35)/3 -> 0.24224369 | I35: =SUM($B$35:$D$35)/3 -> 0.24224369 | J35: Historical average of Depreciation Expense / PP&E BoY
A36: Stock comp growth | C36: =+C19/B19-1 -> 0.42714151 | D36: =+D19/C19-1 -> -0.41025837 | E36: 0.025 | F36: 0.025 | G36: 0.025 | H36: 0.025 | I36: 0.025 | J36: Grows with inflation
A37: Content amortization | C37: =C20/B20 -1 -> 0.14682838 | D37: =D20/C20 -1 -> 0.012213274 | E37: 0.07 | F37: 0.08 | G37: 0.08 | H37: 0.09 | I37: 0.09 | J37: High Single Digit Numbers
A39: Adjusted EBITDA

Sheet BS
A1: CONSOLIDATED BALANCE SHEETS - USD ($) $ in Thousands | B1: As of December 31,
B2: 2020 | C2: 2021 | D2: 2022 | E2: 2023 | F2: 2024 | G2: 2025 | H2: 2026 | I2: 2027 | J2: 2028 | K2: Comments
A3: Current assets:
A4: Cash and cash equivalents | B4: 8205550 | C4: 6027804 | D4: 5147176 | E4: 7116913 | F4: =F7-SUM(F5:F6) -> 11468484 | G4: =G7-SUM(G5:G6) -> 18804032 | H4: =H7-SUM(H5:H6) -> 29654191 | I4: =I7-SUM(I5:I6) -> 44805316 | J4: =J7-SUM(J5:J6) -> 64823762 | K4: PLUG to balance
A5: Short-term investments | D5: 911276 | E5: 20973 | F5: =F43 -> 20973 | G5: =G43 -> 20973 | H5: =H43 -> 20973 | I5: =I43 -> 20973 | J5: =J43 -> 20973 | K5: Roll Forward
A6: Other current assets | B6: 1556030 | C6: 2042021 | D6: 3208021 | E6: 2780247 | F6: =E6*(1+IS!E$23) -> 3141679.1 | G6: =F6*(1+IS!F$23) -> 3550097.4 | H6: =G6*(1+IS!G$23) -> 4029360.5 | I6: =H6*(1+IS!H$23) -> 4573324.2 | J6: =I6*(1+IS!I$23) -> 5213589.6 | K6: OA
A7: Total current assets | B7: 9761580 | C7: 8069825 | D7: 9266473 | E7: 9918133 | F7: =F11-SUM(F8:F10) -> 14631136 | G7: =G11-SUM(G8:G10) -> 22375102 | H7: =H11-SUM(H8:H10) -> 33704525 | I7: =I11-SUM(I8:I10) -> 49399613 | J7: =J11-SUM(J8:J10) -> 70058325
A8: Content assets, net | B8: 25383950 | C8: 30919539 | D8: 32736713 | E8: 31658056 | F8: =F37 -> 33466798 | G8: =G37 -> 34060240 | H8: =H37 -> 33341157 | I8: =I37 -> 31027357 | J8: =J37 -> 26975315 | K8: OA, roll forward
A9: Property and equipment, net | B9: 960183 | C9: 1323453 | D9: 1398257 | E9: 1491444 | F9: =F49 -> 1524014.9 | G9: =G49 -> 1599897.9 | H9: =H49 -> 1717482.7 | I9: =I49 -> 1874778.6 | J9: =J49 -> 2074238.8 | K9: roll forward, investing
A10: Other non-current assets | B10: 3174646 | C10: 4271846 | D10: 5193325 | E10: 5664359 | F10: =E10*(1+IS!E$23) -> 6400725.7 | G10: =F10*(1+IS!F$23) -> 7232820 | H10: =G10*(1+IS!G$23) -> 8209250.7 | I10: =H10*(1+IS!H$23) -> 9317499.6 | J10: =I10*(1+IS!I$23) -> 10621949 | K10: OA
A11: Total assets | B11: 39280359 | C11: 44584663 | D11: 48594768 | E11: 48731992 | F11: =F29 -> 56022675 | G11: =G29 -> 65268061 | H11: =H29 -> 76972416 | I11: =I29 -> 91619249 | J11: =J29 -> 1.0972983e+08
A12: Current liabilities:
A13: Current content liabilities | B13: 4429536 | C13: 4292967 | D13: 4480150 | E13: 4466470 | F13: =E13*(1+IS!E$23) -> 5047111.1 | G13: =F13*(1+IS!F$23) -> 5703235.5 | H13: =G13*(1+IS!G$23) -> 6473172.3 | I13: =H13*(1+IS!H$23) -> 7347050.6 | J13: =I13*(1+IS!I$23) -> 8375637.7 | K13: OL
A14: Accounts payable | B14: 656183 | C14: 837483 | D14: 671513 | E14: 747412 | F14: =E14*(1+IS!E$23) -> 844575.56 | G14: =F14*(1+IS!F$23) -> 954370.38 | H14: =G14*(1+IS!G$23) -> 1083210.4 | I14: =H14*(1+IS!H$23) -> 1229443.8 | J14: =I14*(1+IS!I$23) -> 1401565.9 | K14: OL
A15: Accrued expenses and other liabilities | B15: 1102196 | C15: 1449351 | D15: 1514650 | E15: 1803960 | F15: =E15*(1+IS!E$23) -> 2038474.8 | G15: =F15*(1+IS!F$23) -> 2303476.5 | H15: =G15*(1+IS!G$23) -> 2614445.9 | I15: =H15*(1+IS!H$23) -> 2967396 | J15: =I15*(1+IS!I$23) -> 3382831.5 | K15: OL
A16: Deferred revenue | B16: 1117992 | C16: 1209342 | D16: 1264661 | E16: 1442969 | F16: =E16*(1+IS!E$23) -> 1630555 | G16: =F16*(1+IS!F$23) -> 1842527.1 | H16: =G16*(1+IS!G$23) -> 2091268.3 | I16: =H16*(1+IS!H$23) -> 2373589.5 | J16: =I16*(1+IS!I$23) -> 2705892 | K16: OL
A17: Short-term debt | B17: 499878 | C17: 699823 | D17: 0 | E17: 399844 | F17: =E17 -> 399844 | G17: =F17 -> 399844 | H17: =G17 -> 399844 | I17: =H17 -> 399844 | J17: =I17 -> 399844 | K17: OL
A18: Total current liabilities | B18: 7805785 | C18: 8488966 | D18: 7930974 | E18: 8860655 | F18: =SUM(F13:F17) -> 9960560.4 | G18: =SUM(G13:G17) -> 11203454 | H18: =SUM(H13:H17) -> 12661941 | I18: =SUM(I13:I17) -> 14317324 | J18: =SUM(J13:J17) -> 16265771
A19: Non-current content liabilities | B19: 2618084 | C19: 3094213 | D19: 3081277 | E19: 2578173 | F19: =E19*(1+IS!E$23) -> 2913335.5 | G19: =F19*(1+IS!F$23) -> 3292069.1 | H19: =G19*(1+IS!G$23) -> 3736498.4 | I19: =H19*(1+IS!H$23) -> 4240925.7 | J19: =I19*(1+IS!I$23) -> 4834655.3 | K19: OL
A20: Long-term debt | B20: 15809095 | C20: 14693072 | D20: 14353076 | E20: 14143417 | F20: =F55 -> 14139417 | G20: =G55 -> 14135417 | H20: =H55 -> 14131417 | I20: =I55 -> 14127417 | J20: =J55 -> 14123417 | K20: roll forward
A21: Other non-current liabilities | B21: 1982155 | C21: 2459164 | D21: 2452040 | E21: 2561434 | F21: =E21*(1+IS!E$23) -> 2894420.4 | G21: =F21*(1+IS!F$23) -> 3270695.1 | H21: =G21*(1+IS!G$23) -> 3712238.9 | I21: =H21*(1+IS!H$23) -> 4213391.2 | J21: =I21*(1+IS!I$23) -> 4803265.9 | K21: OL
A22: Total liabilities | B22: 28215119 | C22: 28735415 | D22: 27817367 | E22: 28143679 | F22: =SUM(F18:F21) -> 29907733 | G22: =SUM(G18:G21) -> 31901635 | H22: =SUM(H18:H21) -> 34242095 | I22: =SUM(I18:I21) -> 36899058 | J22: =SUM(J18:J21) -> 40027109
A23: Stockholders’ equity:
A24: Common stock | B24: 3447698 | C24: 4024561 | D24: 4637601 | E24: 5145172 | F24: =F61 -> 5493024.2 | G24: =G61 -> 5849572.7 | H24: =H61 -> 6215034.9 | I24: =I61 -> 6589633.7 | J24: =J61 -> 6973597.4 | K24: roll forward
A25: Treasury stock at cost | B25: 0 | C25: -824190 | D25: -824190 | E25: -6922200 | F25: =F66 -> -8602200 | G25: =G66 -> -10282200 | H25: =H66 -> -11962200 | I25: =I66 -> -13642200 | J25: =J66 -> -15322200 | K25: roll forward
A26: Accumulated other comprehensive income (loss) | B26: 44398 | C26: -40495 | D26: -217306 | E26: -223945 | F26: =F77 -> -223945 | G26: =G77 -> -223945 | H26: =H77 -> -223945 | I26: =I77 -> -223945 | J26: =J77 -> -223945 | K26: roll forward
A27: Retained earnings | B27: 7573144 | C27: 12689372 | D27: 17181296 | E27: 22589286 | F27: =F72 -> 29448063 | G27: =G72 -> 38022998 | H27: =H72 -> 48701431 | I27: =I72 -> 61996702 | J27: =J72 -> 78275266 | K27: roll forward
A28: Total stockholders’ equity | B28: 11065240 | C28: 15849248 | D28: 20777401 | E28: 20588313 | F28: =SUM(F24:F27) -> 26114942 | G28: =SUM(G24:G27) -> 33366426 | H28: =SUM(H24:H27) -> 42730320 | I28: =SUM(I24:I27) -> 54720191 | J28: =SUM(J24:J27) -> 69702719
A29: Total liabilities and stockholders’ equity | B29: 39280359 | C29: 44584663 | D29: 48594768 | E29: 48731992 | F29: =F28+F22 -> 56022675 | G29: =G28+G22 -> 65268061 | H29: =H28+H22 -> 76972416 | I29: =I28+I22 -> 91619249 | J29: =J28+J22 -> 1.0972983e+08
A32: Balance Sheet Rollforwards | K32: Comments
A33: Content assets, net | E33: FY23 SCF
A34: BOY | F34: =BS!E8 -> 31658056 | G34: =BS!F8 -> 33466798 | H34: =BS!G8 -> 34060240 | I34: =BS!H8 -> 33341157 | J34: =BS!I8 -> 31027357
A35: Add: Net additions | E35: 12554703 | F35: =17000000 -> 17000000 | G35: =17000000 -> 17000000 | H35: =17000000 -> 17000000 | I35: =17000000 -> 17000000 | J35: =17000000 -> 17000000 | K35: MGMT guidence, assume $17 billion
A36: Less: Content amortization* | F36: =-IS!E20 -> -15191258 | G36: =-IS!F20 -> -16406558 | H36: =-IS!G20 -> -17719083 | I36: =-IS!H20 -> -19313800 | J36: =-IS!I20 -> -21052042
A37: EOY | F37: =SUM(F34:F36) -> 33466798 | G37: =SUM(G34:G36) -> 34060240 | H37: =SUM(H34:H36) -> 33341157 | I37: =SUM(I34:I36) -> 31027357 | J37: =SUM(J34:J36) -> 26975315
A39: Short-term Investments
A40: BOY | F40: =E5 -> 20973 | G40: =F43 -> 20973 | H40: =G43 -> 20973 | I40: =H43 -> 20973 | J40: =I43 -> 20973
A41: ±net additions or disposals | F41: 0 | G41: 0 | H41: 0 | I41: 0 | J41: 0
A42: ±gains/losses or other non-cash adjustments* | F42: 0 | G42: 0 | H42: 0 | I42: 0 | J42: 0
A43: EOY | F43: =SUM(F40:F42) -> 20973 | G43: =SUM(G40:G42) -> 20973 | H43: =SUM(H40:H42) -> 20973 | I43: =SUM(I40:I42) -> 20973 | J43: =SUM(J40:J42) -> 20973
...

Sheet SCF forecast
A1: CASH FLOW STATEMENTS - USD ($) $ in Thousands | B1: 12 Months Ended December 31,
B2: 2024 | C2: 2025 | D2: 2026 | E2: 2027 | F2: 2028
A3: Net Income | B3: =BS!F70 -> 6858776.6 | C3: =BS!G70 -> 8574935.5 | D3: =BS!H70 -> 10678432 | E3: =BS!I70 -> 13295272 | F3: =BS!J70 -> 16278564
A4: Add: Depreciation | B4: =-BS!F48 -> 361292.9 | C4: =-BS!G48 -> 369182.98 | D4: =-BS!H48 -> 387565.18 | E4: =-BS!I48 -> 416049.35 | F4: =-BS!J48 -> 454153.28
A5: Add: Stock Compensation | B5: =BS!F60 -> 347852.2 | C5: =BS!G60 -> 356548.5 | D5: =BS!H60 -> 365462.22 | E5: =BS!I60 -> 374598.77 | F5: =BS!J60 -> 383963.74
A6: Add: Amortization of Content | B6: =-BS!F36 -> 15191258 | C6: =-BS!G36 -> 16406558 | D6: =-BS!H36 -> 17719083 | E6: =-BS!I36 -> 19313800 | F6: =-BS!J36 -> 21052042
A7: Change in OA and OL
A8: =BS!A6 -> Other current assets | B8: =BS!E6-BS!F6 -> -361432.11 | C8: =BS!F6-BS!G6 -> -408418.28 | D8: =BS!G6-BS!H6 -> -479263.15 | E8: =BS!H6-BS!I6 -> -543963.67 | F8: =BS!I6-BS!J6 -> -640265.39
A9: =BS!A10 -> Other non-current assets | B9: =BS!E10-BS!F10 -> -736366.67 | C9: =BS!F10-BS!G10 -> -832094.34 | D9: =BS!G10-BS!H10 -> -976430.7 | E9: =BS!H10-BS!I10 -> -1108248.8 | F9: =BS!I10-BS!J10 -> -1304449.9
A10: =BS!A13 -> Current content liabilities | B10: =BS!F13-BS!E13 -> 580641.1 | C10: =BS!G13-BS!F13 -> 656124.44 | D10: =BS!H13-BS!G13 -> 769936.8 | E10: =BS!I13-BS!H13 -> 873878.27 | F10: =BS!J13-BS!I13 -> 1028587.1
A11: =BS!A14 -> Accounts payable | B11: =BS!F14-BS!E14 -> 97163.56 | C11: =BS!G14-BS!F14 -> 109794.82 | D11: =BS!H14-BS!G14 -> 128840 | E11: =BS!I14-BS!H14 -> 146233.4 | F11: =BS!J14-BS!I14 -> 172122.13
A12: =BS!A15 -> Accrued expenses and other liabilities | B12: =BS!F15-BS!E15 -> 234514.8 | C12: =BS!G15-BS!F15 -> 265001.72 | D12: =BS!H15-BS!G15 -> 310969.33 | E12: =BS!I15-BS!H15 -> 352950.19 | F12: =BS!J15-BS!I15 -> 415435.45
A13: =BS!A16 -> Deferred revenue | B13: =BS!F16-BS!E16 -> 187585.97 | C13: =BS!G16-BS!F16 -> 211972.15 | D13: =BS!H16-BS!G16 -> 248741.16 | E13: =BS!I16-BS!H16 -> 282321.22 | F13: =BS!J16-BS!I16 -> 332302.53
A14: =BS!A19 -> Non-current content liabilities | B14: =BS!F19-BS!E19 -> 335162.49 | C14: =BS!G19-BS!F19 -> 378733.61 | D14: =BS!H19-BS!G19 -> 444429.33 | E14: =BS!I19-BS!H19 -> 504427.29 | F14: =BS!J19-BS!I19 -> 593729.6
A15: =BS!A21 -> Other non-current liabilities | B15: =BS!F21-BS!E21 -> 332986.42 | C15: =BS!G21-BS!F21 -> 376274.65 | D15: =BS!H21-BS!G21 -> 441543.84 | E15: =BS!I21-BS!H21 -> 501152.25 | F15: =BS!J21-BS!I21 -> 589874.76
A16: Less: Additions to Content assets | B16: =-BS!F35 -> -17000000 | C16: =-BS!G35 -> -17000000 | D16: =-BS!H35 -> -17000000 | E16: =-BS!I35 -> -17000000 | F16: =-BS!J35 -> -17000000
A17: Operating cash flow | B17: =SUM(B3:B16) -> 6429434.8 | C17: =SUM(C3:C16) -> 9464614 | D17: =SUM(D3:D16) -> 13039309 | E17: =SUM(E3:E16) -> 17408470 | F17: =SUM(F3:F16) -> 22356060
A18: Purchase of PP&E (CAPEX) | B18: =-BS!F47 -> -393863.76 | C18: =-BS!G47 -> -445066.05 | D18: =-BS!H47 -> -505149.97 | E18: =-BS!I47 -> -573345.21 | F18: =-BS!J47 -> -653613.54
A19: Purchase of short term investments | B19: =-BS!F41 -> 0 | C19: =-BS!G41 -> 0 | D19: =-BS!H41 -> 0 | E19: =-BS!I41 -> 0 | F19: =-BS!J41 -> 0
A20: Investing cash flow | B20: =SUM(B18:B19) -> -393863.76 | C20: =SUM(C18:C19) -> -445066.05 | D20: =SUM(D18:D19) -> -505149.97 | E20: =SUM(E18:E19) -> -573345.21 | F20: =SUM(F18:F19) -> -653613.54
A21: Cash paid to retire LT debt | B21: =BS!F54 -> -4000 | C21: =BS!G54 -> -4000 | D21: =BS!H54 -> -4000 | E21: =BS!I54 -> -4000 | F21: =BS!J54 -> -4000
A22: Cash received for issuance of C/S | B22: =BS!F59 -> 0 | C22: =BS!G59 -> 0 | D22: =BS!H59 -> 0 | E22: =BS!I59 -> 0 | F22: =BS!J59 -> 0
A23: Cash Paid for Treasury Stock Repurchase | B23: =BS!F65 -> -1680000 | C23: =BS!G65 -> -1680000 | D23: =BS!H65 -> -1680000 | E23: =BS!I65 -> -1680000 | F23: =BS!J65 -> -1680000
A24: Cash Paid to retire short term debt | B24: =BS!E17-BS!F17 -> 0 | C24: =BS!F17-BS!G17 -> 0 | D24: =BS!G17-BS!H17 -> 0 | E24: =BS!H17-BS!I17 -> 0 | F24: =BS!I17-BS!J17 -> 0
A25: Cash received for issuance of LT debt | B25: =BS!F53 -> 0 | C25: =BS!G53 -> 0 | D25: =BS!H53 -> 0 | E25: =BS!I53 -> 0 | F25: =BS!J53 -> 0
A26: Financing Cash flow | B26: =SUM(B21:B25) -> -1684000 | C26: =SUM(C21:C25) -> -1684000 | D26: =SUM(D21:D25) -> -1684000 | E26: =SUM(E21:E25) -> -1684000 | F26: =SUM(F21:F25) -> -1684000
A28: Net change in cash | B28: =B17+B20+B26 -> 4351571.1 | C28: =C17+C20+C26 -> 7335548 | D28: =D17+D20+D26 -> 10850159 | E28: =E17+E20+E26 -> 15151125 | F28: =F17+F20+F26 -> 20018446
B29: =BS!F4-BS!E4 -> 4351571.1 | C29: =BS!G4-BS!F4 -> 7335548 | D29: =BS!H4-BS!G4 -> 10850159 | E29: =BS!I4-BS!H4 -> 15151125 | F29: =BS!J4-BS!I4 -> 20018446

Sheet DCF
A3: Enterprise Free Cash Flow (FCFF)
A4: Year: (n) | C4: 2024 | D4: 2025 | E4: 2026 | F4: 2027 | G4: 2028
A5: EBIT | C5: =IS!E15-IS!E14-IS!E11 -> 8597623.6 | D5: =IS!F15-IS!F14-IS!F11 -> 10576942 | E5: =IS!G15-IS!G14-IS!G11 -> 13003036 | F5: =IS!H15-IS!H14-IS!H11 -> 16021246 | G5: =IS!I15-IS!I14-IS!I11 -> 19462142
A6: Less: Implied income taxes | C6: =-C5*IS!E33 -> -1143804.3 | D6: =-D5*IS!F33 -> -1407127.3 | E6: =-E5*IS!G33 -> -1729888.2 | F6: =-F5*IS!H33 -> -2131422.6 | G6: =-G5*IS!I33 -> -2589190
A7: EBIT, net implied taxed | C7: =SUM(C5:C6) -> 7453819.3 | D7: =SUM(D5:D6) -> 9169814.6 | E7: =SUM(E5:E6) -> 11273148 | F7: =SUM(F5:F6) -> 13889823 | G7: =SUM(G5:G6) -> 16872952 | H7: NOPAT
A8: Add: depreciation | C8: ='SCF forecast'!B4 -> 361292.9 | D8: ='SCF forecast'!C4 -> 369182.98 | E8: ='SCF forecast'!D4 -> 387565.18 | F8: ='SCF forecast'!E4 -> 416049.35 | G8: ='SCF forecast'!F4 -> 454153.28
A9: add: stock compensation | C9: ='SCF forecast'!B5 -> 347852.2 | D9: ='SCF forecast'!C5 -> 356548.5 | E9: ='SCF forecast'!D5 -> 365462.22 | F9: ='SCF forecast'!E5 -> 374598.77 | G9: ='SCF forecast'!F5 -> 383963.74
A10: add: amortization | C10: ='SCF forecast'!B6 -> 15191258 | D10: ='SCF forecast'!C6 -> 16406558 | E10: ='SCF forecast'!D6 -> 17719083 | F10: ='SCF forecast'!E6 -> 19313800 | G10: ='SCF forecast'!F6 -> 21052042
A11: Change in non-cash OA and OL | C11: =SUM('SCF forecast'!B8:B16) -> -16329744 | D11: =SUM('SCF forecast'!C8:C16) -> -16242611 | E11: =SUM('SCF forecast'!D8:D16) -> -16111233 | F11: =SUM('SCF forecast'!E8:E16) -> -15991250 | G11: =SUM('SCF forecast'!F8:F16) -> -15812664
A12: Subtotal | C12: =SUM(C7:C11) -> 7024477.5 | D12: =SUM(D7:D11) -> 10059493 | E12: =SUM(E7:E11) -> 13634025 | F12: =SUM(F7:F11) -> 18003022 | G12: =SUM(G7:G11) -> 22950448
A13: CAPEX | C13: ='SCF forecast'!B18 -> -393863.76 | D13: ='SCF forecast'!C18 -> -445066.05 | E13: ='SCF forecast'!D18 -> -505149.97 | F13: ='SCF forecast'!E18 -> -573345.21 | G13: ='SCF forecast'!F18 -> -653613.54
A14: FCFF | C14: =SUM(C12:C13) -> 6630613.8 | D14: =SUM(D12:D13) -> 9614427 | E14: =SUM(E12:E13) -> 13128875 | F14: =SUM(F12:F13) -> 17429677 | G14: =SUM(G12:G13) -> 22296834
A19: Enterprise Value [DCF] Model
A20: Modeling Assumptions:
A21: Discount rate | B21: 0.1
A22: TV growth rate | B22: 0.03
B23: 0 | C23: 1 | D23: 2 | E23: 3 | F23: 4 | G23: 5 | K23: Discount Rate
A24: FCFF | C24: =C14 -> 6630613.8 | D24: =D14 -> 9614427 | E24: =E14 -> 13128875 | F24: =F14 -> 17429677 | G24: =G14 -> 22296834 | J24: =B30/1000 -> 253299.94 | K24: 0.08 | L24: 0.08 | M24: 0.09 | N24: 0.095 | O24: 0.1
A25: TV | G25: =G24*(1+B22)/(B21-B22) -> 3.2808199e+08 | I25: growth rate | J25: 0.02 | K25: 310763.05 | L25: 310763.05 | M25: 262312.92 | N25: 242985.25 | O25: 226105.23
C26: =C24+C25 -> 6630613.8 | D26: =D24+D25 -> 9614427 | E26: =E24+E25 -> 13128875 | F26: =F24+F25 -> 17429677 | G26: =G24+G25 -> 3.5037882e+08 | J26: 0.025 | K26: 335594.62 | L26: 335594.62 | M26: 279670.76 | N26: 257755.82 | O26: 238796.1
A27: PV factor | C27: =(1+$B$21)^C23 -> 1.1 | D27: =(1+$B$21)^D23 -> 1.21 | E27: =(1+$B$21)^E23 -> 1.331 | F27: =(1+$B$21)^F23 -> 1.4641 | G27: =(1+$B$21)^G23 -> 1.61051 | J27: 0.0275 | K27: 349784.09 | L27: 349784.09 | M27: 289391.16 | N27: 265961.7 | O27: 245797.95
C28: =C26/C27 -> 6027830.7 | D28: =D26/D27 -> 7945807.4 | E28: =E26/E27 -> 9863917.8 | F28: =F26/F27 -> 11904704 | G28: =G26/G27 -> 2.1755768e+08 | J28: 0.03 | K28: 365392.51 | L28: 365392.51 | M28: 299921.58 | N28: 274798.8 | O28: 253299.94
J29: 0.035 | K29: 401812.15 | L29: 401812.15 | M29: 323854.37 | N29: 294682.26 | O29: 270035.15
A30: Enterprise Value [Model] | B30: =SUM(C28:G28) -> 2.5329994e+08
